<?xml version="1.0"?>
<robot xmlns:xacro="http://ros.org/wiki/xacro">
  <property name="M_PI" value="3.1415926535897931" />
  <xacro:property name="M_PI" value="3.1415926535897931" />

  <xacro:macro name="pioneer_wheel" params="side parent xyz rpy radius meshes">

    <xacro:macro name="inertial_matrix" params="mass">
      <inertial>
        <mass value="${mass}" />
        <inertia ixx="1.0" ixy="0.0" ixz="0.0" iyy="0.5" iyz="0.0" izz="1.0" />
      </inertial>
    </xacro:macro>

    <xacro:macro name="transmission_block" params="joint_name">
      <transmission name="${joint_name}_tran1">
        <type>transmission_interface/SimpleTransmission</type>
        <joint name="${joint_name}">
          <hardwareInterface>hardware_interface/PositionJointInterface</hardwareInterface>
        </joint>
        <actuator name="${joint_name}_motor">
        <hardwareInterface>hardware_interface/PositionJointInterface</hardwareInterface>
          <mechanicalReduction>1</mechanicalReduction>
        </actuator>
      </transmission>
    </xacro:macro>

    <xacro:transmission_block joint_name="${side}_prismatic_joint"/>
    <xacro:transmission_block joint_name="${side}_prismatic_joint1"/>

    <!-- Hubcap -->
    <joint name="${side}_hub_joint" type="continuous">
      <origin xyz="${xyz}" rpy="${rpy}"/>
      <parent link="${parent}"/>
      <child link="${side}_hub"/>
      <axis xyz="0 1 0"/>
    </joint>
    <link name="${side}_hub">
      <inertial>
        <mass value="0.01"/>
        <origin xyz="0 0 0"/>
        <inertia ixx="0.012411765597" ixy="0" ixz="0" iyy="0.015218160428" iyz="0" izz="0.011763977943"/>
      </inertial>
      <visual name="base_visual">
        <origin xyz="0 0 0" rpy="0 0 0"/>
        <geometry name="pioneer_geom">
          <mesh filename="${meshes}/${side}_hubcap.stl"/>
        </geometry>
        <material name="HubcapYellow">
          <color rgba="1.0 0.811 0.151 1.0"/>
        </material>
      </visual>
      <collision>
        <origin xyz="0 0 0" rpy="0 0 0"/>
        <geometry>
          <box size="0.01 0.01 0.01"/>
        </geometry>
      </collision>
    </link>
    <gazebo reference="${side}_hub">
      <material value="Gazebo/Yellow"/>
    </gazebo>

    <!-- Wheel -->
    <joint name="${side}_wheel_joint" type="fixed">
      <axis xyz="0 1 0"/>
      <origin xyz="0 0 0" rpy="0 0 0"/>
      <parent link="${side}_hub"/>
      <child link="${side}_wheel"/>
    </joint>
    <link name="${side}_wheel">
      <inertial>
        <mass value="0.5"/>
        <origin xyz="0 0 0"/>
        <inertia ixx="0.012411765597" ixy="0" ixz="0" iyy="0.015218160428" iyz="0" izz="0.011763977943"/>
      </inertial>
      <visual name="base_visual">
        <origin xyz="0 0 0" rpy="0 0 0"/>
        <geometry name="pioneer_geom">
          <mesh filename="${meshes}/${side}_wheel.stl"/>
        </geometry>
        <material name="WheelBlack">
          <color rgba="0.117 0.117 0.117 1"/>
        </material>
      </visual>
      <collision>
        <origin xyz="0 0 0" rpy="${-3.1415927/2} 0 0"/>
        <geometry>
          <!--<mesh filename="${meshes}/${side}_wheel.stl"/>-->
          <cylinder radius="${radius}" length="0.01"/>
        </geometry>
      </collision>
    </link>
    <gazebo reference="${side}_wheel">
      <material value="Gazebo/Black"/>
    </gazebo>


    <!-- Prizmatic joint and link 1 also it is plugins -->
    <joint name="${side}_prismatic_joint" type="prismatic">
      <parent link="${side}_hub"/>
      <child link="${side}_wheel_prismatic"/>
      <origin xyz="0.0 0 0" />
      <axis xyz="0 0 1" />
      <limit effort="1000" lower="0.02" upper="0.05" velocity="1.0"/>
      <dynamics damping="50" friction="1"/>
    </joint>
    <link name="${side}_wheel_prismatic">
      <xacro:inertial_matrix mass="1"/>
      <visual>
        <origin xyz="0 0 0.03" rpy="0 0 0"/>
        <geometry>
          <box size="0.01 0.01 0.08" />
        </geometry>
        <material name="black" />
      </visual>
      <collision name="collision">
        <geometry>
          <box size="0.01 0.01 0.08" />
        </geometry>
      </collision>
    </link>
    <gazebo reference="${side}_wheel_prismatic">
      <material value="Gazebo/Black"/>
    </gazebo>

    <!-- prizamic joint and link right 12 bar -->
    <joint name="${side}_barj_r1" type="fixed">
      <parent link="${side}_wheel_prismatic"/>
      <child link="${side}_bar"/>
      <origin xyz="0 0 0.07" rpy="0 0 ${M_PI/2}"/>
      <axis xyz="0 0 0" />
    </joint>
    <link name="${side}_bar">
      <collision name="collision">
        <geometry>
          <box size="0.01 0.03 0.01" />
        </geometry>
      </collision>
      <visual>
        <origin xyz="0 0 0"/>
        <geometry>
          <box size="0.01 0.03 0.01" />
        </geometry>
        <material name="black" />
      </visual>
      <xacro:inertial_matrix mass="1"/>
    </link>
    <gazebo reference="${side}_bar">
      <material>Gazebo/White</material>
    </gazebo>




    <!-- Prizmatic joint and link 2 -->
    <!-- prizamic joint and link right 13  -->
    <joint name="${side}_prismatic_joint1" type="prismatic">
      <parent link="${side}_hub"/>
      <child link="${side}_prizm2"/>
      <origin xyz="0 0 0" rpy="0 ${M_PI/6} 0"/>
      <axis xyz="0 0 1" />
      <limit effort="1000" lower="0.02" upper="0.05" velocity="1.0"/>
      <dynamics damping="50" friction="1"/>
    </joint>
    <link name="${side}_prizm2">
      <collision name="collision">
        <geometry>
          <box size="0.01 0.01 0.08" />
        </geometry>
      </collision>
      <visual>
        <origin xyz="0 0 0.03"/>
        <geometry>
          <box size="0.01 0.01 0.08" />
        </geometry>
        <material name="black" />
      </visual>
      <xacro:inertial_matrix mass="1"/>
    </link>
    <gazebo reference="${side}_prizm2">
      <material>Gazebo/White</material>
    </gazebo>


    <!-- prizamic joint and link right 12 bar -->
    <joint name="${side}_barj_r2" type="fixed">
      <parent link="${side}_prizm2"/>
      <child link="${side}_bar2"/>
      <origin xyz="0 0 0.07" rpy="0 0 ${M_PI/2}"/>
      <axis xyz="0 0 0" />
    </joint>
    <link name="${side}_bar2">
      <collision name="collision">
        <geometry>
          <box size="0.01 0.03 0.01" />
        </geometry>
      </collision>
      <visual>
        <origin xyz="0 0 0"/>
        <geometry>
          <box size="0.01 0.03 0.01" />
        </geometry>
        <material name="black" />
      </visual>
      <xacro:inertial_matrix mass="1"/>
    </link>
    <gazebo reference="${side}_bar2">
      <material>Gazebo/White</material>
    </gazebo>

    <!--joint_positions publisher -->


  </xacro:macro>

</robot>
