<sdf version='1.7'>
  <world name='default'>
    <light name='sun' type='directional'>
      <cast_shadows>1</cast_shadows>
      <pose>0 0 10 0 -0 0</pose>
      <diffuse>0.8 0.8 0.8 1</diffuse>
      <specular>0.1 0.1 0.1 1</specular>
      <attenuation>
        <range>1000</range>
        <constant>0.9</constant>
        <linear>0.01</linear>
        <quadratic>0.001</quadratic>
      </attenuation>
      <direction>-0.5 0.5 -1</direction>
      <spot>
        <inner_angle>0</inner_angle>
        <outer_angle>0</outer_angle>
        <falloff>0</falloff>
      </spot>
    </light>
    <model name='ground_plane'>
      <static>1</static>
      <link name='link'>
        <collision name='collision'>
          <geometry>
            <plane>
              <normal>0 0 1</normal>
              <size>100 100</size>
            </plane>
          </geometry>
          <surface>
            <friction>
              <ode>
                <mu>100</mu>
                <mu2>50</mu2>
              </ode>
              <torsional>
                <ode/>
              </torsional>
            </friction>
            <contact>
              <ode/>
            </contact>
            <bounce/>
          </surface>
          <max_contacts>10</max_contacts>
        </collision>
        <visual name='visual'>
          <cast_shadows>0</cast_shadows>
          <geometry>
            <plane>
              <normal>0 0 1</normal>
              <size>100 100</size>
            </plane>
          </geometry>
          <material>
            <script>
              <uri>file://media/s/scripts/gazebo.</uri>
              <name>Gazebo/Grey</name>
            </script>
          </material>
        </visual>
        <self_collide>0</self_collide>
        <kinematic>0</kinematic>
        <gravity>1</gravity>
        <enable_wind>0</enable_wind>
      </link>
    </model>
    <gravity>0 0 -9.8</gravity>
    <magnetic_field>6e-06 2.3e-05 -4.2e-05</magnetic_field>
    <atmosphere type='adiabatic'/>
    <physics name='default_physics' default='0' type='ode'>
      <max_step_size>0.001</max_step_size>
      <real_time_factor>1</real_time_factor>
      <real_time_update_rate>1000</real_time_update_rate>
    </physics>
    <scene>
      <ambient>0.4 0.4 0.4 1</ambient>
      <background>0.7 0.7 0.7 1</background>
      <shadows>1</shadows>
    </scene>
    <spherical_coordinates>
      <surface_model>EARTH_WGS84</surface_model>
      <latitude_deg>0</latitude_deg>
      <longitude_deg>0</longitude_deg>
      <elevation>0</elevation>
      <heading_deg>0</heading_deg>
    </spherical_coordinates>
    <model name='box'>
      <link name='Wall_11'>
        <pose>-2.152 1.857 0 0 -0 0</pose>
        <self_collide>0</self_collide>
        <kinematic>0</kinematic>
        <visual name='Wall_11_Visual'>
          <pose>0 0 0.5 0 -0 0</pose>
          <geometry>
            <box>
              <size>2.5 0.15 1</size>
            </box>
          </geometry>
          <material>
            <script>
              <uri>file://media/materials/scripts/gazebo.material</uri>
              <name>Gazebo/CeilingTiled</name>
            </script>
            <ambient>1 1 1 1</ambient>
            <diffuse>1 1 1 1</diffuse>
            <specular>0 0 0 1</specular>
            <emissive>0 0 0 1</emissive>
          </material>
          <meta>
            <layer>0</layer>
          </meta>
          <cast_shadows>1</cast_shadows>
          <transparency>0</transparency>
        </visual>
        <collision name='Wall_11_Collision'>
          <laser_retro>0</laser_retro>
          <max_contacts>10</max_contacts>
          <pose>0 0 0.5 0 -0 0</pose>
          <geometry>
            <box>
              <size>2.5 0.15 1</size>
            </box>
          </geometry>
          <surface>
            <friction>
              <ode>
                <mu>1</mu>
                <mu2>1</mu2>
                <fdir1>0 0 0</fdir1>
                <slip1>0</slip1>
                <slip2>0</slip2>
              </ode>
              <torsional>
                <coefficient>1</coefficient>
                <patch_radius>0</patch_radius>
                <surface_radius>0</surface_radius>
                <use_patch_radius>1</use_patch_radius>
                <ode>
                  <slip>0</slip>
                </ode>
              </torsional>
            </friction>
            <bounce>
              <restitution_coefficient>0</restitution_coefficient>
              <threshold>1e+06</threshold>
            </bounce>
            <contact>
              <collide_without_contact>0</collide_without_contact>
              <collide_without_contact_bitmask>1</collide_without_contact_bitmask>
              <collide_bitmask>1</collide_bitmask>
              <ode>
                <soft_cfm>0</soft_cfm>
                <soft_erp>0.2</soft_erp>
                <kp>1e+13</kp>
                <kd>1</kd>
                <max_vel>0.01</max_vel>
                <min_depth>0</min_depth>
              </ode>
              <bullet>
                <split_impulse>1</split_impulse>
                <split_impulse_penetration_threshold>-0.01</split_impulse_penetration_threshold>
                <soft_cfm>0</soft_cfm>
                <soft_erp>0.2</soft_erp>
                <kp>1e+13</kp>
                <kd>1</kd>
              </bullet>
            </contact>
          </surface>
        </collision>
        <gravity>1</gravity>
        <enable_wind>0</enable_wind>
      </link>
      <link name='Wall_13'>
        <pose>-2.155 1.764 0 0 0 -1.5708</pose>
        <self_collide>0</self_collide>
        <kinematic>0</kinematic>
        <visual name='Wall_13_Visual'>
          <pose>0 0 0.5 0 -0 0</pose>
          <geometry>
            <box>
              <size>2.75 0.15 1</size>
            </box>
          </geometry>
          <material>
            <script>
              <uri>file://media/materials/scripts/gazebo.material</uri>
              <name>Gazebo/CeilingTiled</name>
            </script>
            <ambient>1 1 1 1</ambient>
            <diffuse>1 1 1 1</diffuse>
            <specular>0 0 0 1</specular>
            <emissive>0 0 0 1</emissive>
          </material>
          <meta>
            <layer>0</layer>
          </meta>
          <cast_shadows>1</cast_shadows>
          <transparency>0</transparency>
        </visual>
        <collision name='Wall_13_Collision'>
          <laser_retro>0</laser_retro>
          <max_contacts>10</max_contacts>
          <pose>0 0 0.5 0 -0 0</pose>
          <geometry>
            <box>
              <size>2.75 0.15 1</size>
            </box>
          </geometry>
          <surface>
            <friction>
              <ode>
                <mu>1</mu>
                <mu2>1</mu2>
                <fdir1>0 0 0</fdir1>
                <slip1>0</slip1>
                <slip2>0</slip2>
              </ode>
              <torsional>
                <coefficient>1</coefficient>
                <patch_radius>0</patch_radius>
                <surface_radius>0</surface_radius>
                <use_patch_radius>1</use_patch_radius>
                <ode>
                  <slip>0</slip>
                </ode>
              </torsional>
            </friction>
            <bounce>
              <restitution_coefficient>0</restitution_coefficient>
              <threshold>1e+06</threshold>
            </bounce>
            <contact>
              <collide_without_contact>0</collide_without_contact>
              <collide_without_contact_bitmask>1</collide_without_contact_bitmask>
              <collide_bitmask>1</collide_bitmask>
              <ode>
                <soft_cfm>0</soft_cfm>
                <soft_erp>0.2</soft_erp>
                <kp>1e+13</kp>
                <kd>1</kd>
                <max_vel>0.01</max_vel>
                <min_depth>0</min_depth>
              </ode>
              <bullet>
                <split_impulse>1</split_impulse>
                <split_impulse_penetration_threshold>-0.01</split_impulse_penetration_threshold>
                <soft_cfm>0</soft_cfm>
                <soft_erp>0.2</soft_erp>
                <kp>1e+13</kp>
                <kd>1</kd>
              </bullet>
            </contact>
          </surface>
        </collision>
        <gravity>1</gravity>
        <enable_wind>0</enable_wind>
      </link>
      <link name='Wall_15'>
        <pose>2.724 3.029 0 0 -0 0</pose>
        <self_collide>0</self_collide>
        <kinematic>0</kinematic>
        <visual name='Wall_15_Visual'>
          <pose>0 0 0.5 0 -0 0</pose>
          <geometry>
            <box>
              <size>1.2678 0.15 1</size>
            </box>
          </geometry>
          <material>
            <script>
              <uri>file://media/materials/scripts/gazebo.material</uri>
              <name>Gazebo/Bricks</name>
            </script>
            <ambient>1 1 1 1</ambient>
            <diffuse>1 1 1 1</diffuse>
            <specular>0.2 0.2 0.2 1</specular>
            <emissive>0 0 0 1</emissive>
          </material>
          <meta>
            <layer>0</layer>
          </meta>
          <cast_shadows>1</cast_shadows>
          <transparency>0</transparency>
        </visual>
        <collision name='Wall_15_Collision'>
          <laser_retro>0</laser_retro>
          <max_contacts>10</max_contacts>
          <pose>0 0 0.5 0 -0 0</pose>
          <geometry>
            <box>
              <size>1.2678 0.15 1</size>
            </box>
          </geometry>
          <surface>
            <friction>
              <ode>
                <mu>1</mu>
                <mu2>1</mu2>
                <fdir1>0 0 0</fdir1>
                <slip1>0</slip1>
                <slip2>0</slip2>
              </ode>
              <torsional>
                <coefficient>1</coefficient>
                <patch_radius>0</patch_radius>
                <surface_radius>0</surface_radius>
                <use_patch_radius>1</use_patch_radius>
                <ode>
                  <slip>0</slip>
                </ode>
              </torsional>
            </friction>
            <bounce>
              <restitution_coefficient>0</restitution_coefficient>
              <threshold>1e+06</threshold>
            </bounce>
            <contact>
              <collide_without_contact>0</collide_without_contact>
              <collide_without_contact_bitmask>1</collide_without_contact_bitmask>
              <collide_bitmask>1</collide_bitmask>
              <ode>
                <soft_cfm>0</soft_cfm>
                <soft_erp>0.2</soft_erp>
                <kp>1e+13</kp>
                <kd>1</kd>
                <max_vel>0.01</max_vel>
                <min_depth>0</min_depth>
              </ode>
              <bullet>
                <split_impulse>1</split_impulse>
                <split_impulse_penetration_threshold>-0.01</split_impulse_penetration_threshold>
                <soft_cfm>0</soft_cfm>
                <soft_erp>0.2</soft_erp>
                <kp>1e+13</kp>
                <kd>1</kd>
              </bullet>
            </contact>
          </surface>
        </collision>
        <gravity>1</gravity>
        <enable_wind>0</enable_wind>
      </link>
      <link name='Wall_16'>
        <pose>3.2915 2.6215 0 0 0 -1.54994</pose>
        <self_collide>0</self_collide>
        <kinematic>0</kinematic>
        <visual name='Wall_16_Visual'>
          <pose>0 0 0.5 0 -0 0</pose>
          <geometry>
            <box>
              <size>0.965005 0.15 1</size>
            </box>
          </geometry>
          <material>
            <script>
              <uri>file://media/materials/scripts/gazebo.material</uri>
              <name>Gazebo/Bricks</name>
            </script>
            <ambient>1 1 1 1</ambient>
            <diffuse>1 1 1 1</diffuse>
            <specular>0.2 0.2 0.2 1</specular>
            <emissive>0 0 0 1</emissive>
          </material>
          <meta>
            <layer>0</layer>
          </meta>
          <cast_shadows>1</cast_shadows>
          <transparency>0</transparency>
        </visual>
        <collision name='Wall_16_Collision'>
          <laser_retro>0</laser_retro>
          <max_contacts>10</max_contacts>
          <pose>0 0 0.5 0 -0 0</pose>
          <geometry>
            <box>
              <size>0.965005 0.15 1</size>
            </box>
          </geometry>
          <surface>
            <friction>
              <ode>
                <mu>1</mu>
                <mu2>1</mu2>
                <fdir1>0 0 0</fdir1>
                <slip1>0</slip1>
                <slip2>0</slip2>
              </ode>
              <torsional>
                <coefficient>1</coefficient>
                <patch_radius>0</patch_radius>
                <surface_radius>0</surface_radius>
                <use_patch_radius>1</use_patch_radius>
                <ode>
                  <slip>0</slip>
                </ode>
              </torsional>
            </friction>
            <bounce>
              <restitution_coefficient>0</restitution_coefficient>
              <threshold>1e+06</threshold>
            </bounce>
            <contact>
              <collide_without_contact>0</collide_without_contact>
              <collide_without_contact_bitmask>1</collide_without_contact_bitmask>
              <collide_bitmask>1</collide_bitmask>
              <ode>
                <soft_cfm>0</soft_cfm>
                <soft_erp>0.2</soft_erp>
                <kp>1e+13</kp>
                <kd>1</kd>
                <max_vel>0.01</max_vel>
                <min_depth>0</min_depth>
              </ode>
              <bullet>
                <split_impulse>1</split_impulse>
                <split_impulse_penetration_threshold>-0.01</split_impulse_penetration_threshold>
                <soft_cfm>0</soft_cfm>
                <soft_erp>0.2</soft_erp>
                <kp>1e+13</kp>
                <kd>1</kd>
              </bullet>
            </contact>
          </surface>
        </collision>
        <gravity>1</gravity>
        <enable_wind>0</enable_wind>
      </link>
      <link name='Wall_17'>
        <pose>2.75 2.214 0 0 -0 3.14159</pose>
        <self_collide>0</self_collide>
        <kinematic>0</kinematic>
        <visual name='Wall_17_Visual'>
          <pose>0 0 0.5 0 -0 0</pose>
          <geometry>
            <box>
              <size>1.25 0.15 1</size>
            </box>
          </geometry>
          <material>
            <script>
              <uri>file://media/materials/scripts/gazebo.material</uri>
              <name>Gazebo/Bricks</name>
            </script>
            <ambient>1 1 1 1</ambient>
            <diffuse>1 1 1 1</diffuse>
            <specular>0.2 0.2 0.2 1</specular>
            <emissive>0 0 0 1</emissive>
          </material>
          <meta>
            <layer>0</layer>
          </meta>
          <cast_shadows>1</cast_shadows>
          <transparency>0</transparency>
        </visual>
        <collision name='Wall_17_Collision'>
          <laser_retro>0</laser_retro>
          <max_contacts>10</max_contacts>
          <pose>0 0 0.5 0 -0 0</pose>
          <geometry>
            <box>
              <size>1.25 0.15 1</size>
            </box>
          </geometry>
          <surface>
            <friction>
              <ode>
                <mu>1</mu>
                <mu2>1</mu2>
                <fdir1>0 0 0</fdir1>
                <slip1>0</slip1>
                <slip2>0</slip2>
              </ode>
              <torsional>
                <coefficient>1</coefficient>
                <patch_radius>0</patch_radius>
                <surface_radius>0</surface_radius>
                <use_patch_radius>1</use_patch_radius>
                <ode>
                  <slip>0</slip>
                </ode>
              </torsional>
            </friction>
            <bounce>
              <restitution_coefficient>0</restitution_coefficient>
              <threshold>1e+06</threshold>
            </bounce>
            <contact>
              <collide_without_contact>0</collide_without_contact>
              <collide_without_contact_bitmask>1</collide_without_contact_bitmask>
              <collide_bitmask>1</collide_bitmask>
              <ode>
                <soft_cfm>0</soft_cfm>
                <soft_erp>0.2</soft_erp>
                <kp>1e+13</kp>
                <kd>1</kd>
                <max_vel>0.01</max_vel>
                <min_depth>0</min_depth>
              </ode>
              <bullet>
                <split_impulse>1</split_impulse>
                <split_impulse_penetration_threshold>-0.01</split_impulse_penetration_threshold>
                <soft_cfm>0</soft_cfm>
                <soft_erp>0.2</soft_erp>
                <kp>1e+13</kp>
                <kd>1</kd>
              </bullet>
            </contact>
          </surface>
        </collision>
        <gravity>1</gravity>
        <enable_wind>0</enable_wind>
      </link>
      <link name='Wall_18'>
        <pose>2.1825 2.6215 0 0 -0 1.61372</pose>
        <self_collide>0</self_collide>
        <kinematic>0</kinematic>
        <visual name='Wall_18_Visual'>
          <pose>0 0 0.5 0 -0 0</pose>
          <geometry>
            <box>
              <size>0.965005 0.15 1</size>
            </box>
          </geometry>
          <material>
            <script>
              <uri>file://media/materials/scripts/gazebo.material</uri>
              <name>Gazebo/Bricks</name>
            </script>
            <ambient>1 1 1 1</ambient>
            <diffuse>1 1 1 1</diffuse>
            <specular>0.2 0.2 0.2 1</specular>
            <emissive>0 0 0 1</emissive>
          </material>
          <meta>
            <layer>0</layer>
          </meta>
          <cast_shadows>1</cast_shadows>
          <transparency>0</transparency>
        </visual>
        <collision name='Wall_18_Collision'>
          <laser_retro>0</laser_retro>
          <max_contacts>10</max_contacts>
          <pose>0 0 0.5 0 -0 0</pose>
          <geometry>
            <box>
              <size>0.965005 0.15 1</size>
            </box>
          </geometry>
          <surface>
            <friction>
              <ode>
                <mu>1</mu>
                <mu2>1</mu2>
                <fdir1>0 0 0</fdir1>
                <slip1>0</slip1>
                <slip2>0</slip2>
              </ode>
              <torsional>
                <coefficient>1</coefficient>
                <patch_radius>0</patch_radius>
                <surface_radius>0</surface_radius>
                <use_patch_radius>1</use_patch_radius>
                <ode>
                  <slip>0</slip>
                </ode>
              </torsional>
            </friction>
            <bounce>
              <restitution_coefficient>0</restitution_coefficient>
              <threshold>1e+06</threshold>
            </bounce>
            <contact>
              <collide_without_contact>0</collide_without_contact>
              <collide_without_contact_bitmask>1</collide_without_contact_bitmask>
              <collide_bitmask>1</collide_bitmask>
              <ode>
                <soft_cfm>0</soft_cfm>
                <soft_erp>0.2</soft_erp>
                <kp>1e+13</kp>
                <kd>1</kd>
                <max_vel>0.01</max_vel>
                <min_depth>0</min_depth>
              </ode>
              <bullet>
                <split_impulse>1</split_impulse>
                <split_impulse_penetration_threshold>-0.01</split_impulse_penetration_threshold>
                <soft_cfm>0</soft_cfm>
                <soft_erp>0.2</soft_erp>
                <kp>1e+13</kp>
                <kd>1</kd>
              </bullet>
            </contact>
          </surface>
        </collision>
        <gravity>1</gravity>
        <enable_wind>0</enable_wind>
      </link>
      <link name='Wall_24'>
        <pose>-2.89576 -2.49088 0 0 -0 1.09459</pose>
        <self_collide>0</self_collide>
        <kinematic>0</kinematic>
        <visual name='Wall_24_Visual'>
          <pose>0 0 0.5 0 -0 0</pose>
          <geometry>
            <box>
              <size>1.97704 0.15 1</size>
            </box>
          </geometry>
          <material>
            <script>
              <uri>file://media/materials/scripts/gazebo.material</uri>
              <name>Gazebo/Bricks</name>
            </script>
            <ambient>1 1 1 1</ambient>
            <diffuse>1 1 1 1</diffuse>
            <specular>0.2 0.2 0.2 1</specular>
            <emissive>0 0 0 1</emissive>
          </material>
          <meta>
            <layer>0</layer>
          </meta>
          <cast_shadows>1</cast_shadows>
          <transparency>0</transparency>
        </visual>
        <collision name='Wall_24_Collision'>
          <laser_retro>0</laser_retro>
          <max_contacts>10</max_contacts>
          <pose>0 0 0.5 0 -0 0</pose>
          <geometry>
            <box>
              <size>1.97704 0.15 1</size>
            </box>
          </geometry>
          <surface>
            <friction>
              <ode>
                <mu>1</mu>
                <mu2>1</mu2>
                <fdir1>0 0 0</fdir1>
                <slip1>0</slip1>
                <slip2>0</slip2>
              </ode>
              <torsional>
                <coefficient>1</coefficient>
                <patch_radius>0</patch_radius>
                <surface_radius>0</surface_radius>
                <use_patch_radius>1</use_patch_radius>
                <ode>
                  <slip>0</slip>
                </ode>
              </torsional>
            </friction>
            <bounce>
              <restitution_coefficient>0</restitution_coefficient>
              <threshold>1e+06</threshold>
            </bounce>
            <contact>
              <collide_without_contact>0</collide_without_contact>
              <collide_without_contact_bitmask>1</collide_without_contact_bitmask>
              <collide_bitmask>1</collide_bitmask>
              <ode>
                <soft_cfm>0</soft_cfm>
                <soft_erp>0.2</soft_erp>
                <kp>1e+13</kp>
                <kd>1</kd>
                <max_vel>0.01</max_vel>
                <min_depth>0</min_depth>
              </ode>
              <bullet>
                <split_impulse>1</split_impulse>
                <split_impulse_penetration_threshold>-0.01</split_impulse_penetration_threshold>
                <soft_cfm>0</soft_cfm>
                <soft_erp>0.2</soft_erp>
                <kp>1e+13</kp>
                <kd>1</kd>
              </bullet>
            </contact>
          </surface>
        </collision>
        <gravity>1</gravity>
        <enable_wind>0</enable_wind>
      </link>
      <link name='Wall_25'>
        <pose>-1.97077 -2.49088 0 0 0 -1.01325</pose>
        <self_collide>0</self_collide>
        <kinematic>0</kinematic>
        <visual name='Wall_25_Visual'>
          <pose>0 0 0.5 0 -0 0</pose>
          <geometry>
            <box>
              <size>2.06356 0.15 1</size>
            </box>
          </geometry>
          <material>
            <script>
              <uri>file://media/materials/scripts/gazebo.material</uri>
              <name>Gazebo/Bricks</name>
            </script>
            <ambient>1 1 1 1</ambient>
            <diffuse>1 1 1 1</diffuse>
            <specular>0.2 0.2 0.2 1</specular>
            <emissive>0 0 0 1</emissive>
          </material>
          <meta>
            <layer>0</layer>
          </meta>
          <cast_shadows>1</cast_shadows>
          <transparency>0</transparency>
        </visual>
        <collision name='Wall_25_Collision'>
          <laser_retro>0</laser_retro>
          <max_contacts>10</max_contacts>
          <pose>0 0 0.5 0 -0 0</pose>
          <geometry>
            <box>
              <size>2.06356 0.15 1</size>
            </box>
          </geometry>
          <surface>
            <friction>
              <ode>
                <mu>1</mu>
                <mu2>1</mu2>
                <fdir1>0 0 0</fdir1>
                <slip1>0</slip1>
                <slip2>0</slip2>
              </ode>
              <torsional>
                <coefficient>1</coefficient>
                <patch_radius>0</patch_radius>
                <surface_radius>0</surface_radius>
                <use_patch_radius>1</use_patch_radius>
                <ode>
                  <slip>0</slip>
                </ode>
              </torsional>
            </friction>
            <bounce>
              <restitution_coefficient>0</restitution_coefficient>
              <threshold>1e+06</threshold>
            </bounce>
            <contact>
              <collide_without_contact>0</collide_without_contact>
              <collide_without_contact_bitmask>1</collide_without_contact_bitmask>
              <collide_bitmask>1</collide_bitmask>
              <ode>
                <soft_cfm>0</soft_cfm>
                <soft_erp>0.2</soft_erp>
                <kp>1e+13</kp>
                <kd>1</kd>
                <max_vel>0.01</max_vel>
                <min_depth>0</min_depth>
              </ode>
              <bullet>
                <split_impulse>1</split_impulse>
                <split_impulse_penetration_threshold>-0.01</split_impulse_penetration_threshold>
                <soft_cfm>0</soft_cfm>
                <soft_erp>0.2</soft_erp>
                <kp>1e+13</kp>
                <kd>1</kd>
              </bullet>
            </contact>
          </surface>
        </collision>
        <gravity>1</gravity>
        <enable_wind>0</enable_wind>
      </link>
      <link name='Wall_26'>
        <pose>-2.38953 -3.28527 0 0 -0 3.14159</pose>
        <self_collide>0</self_collide>
        <kinematic>0</kinematic>
        <visual name='Wall_26_Visual'>
          <pose>0 0 0.5 0 -0 0</pose>
          <geometry>
            <box>
              <size>2 0.15 1</size>
            </box>
          </geometry>
          <material>
            <script>
              <uri>file://media/materials/scripts/gazebo.material</uri>
              <name>Gazebo/Bricks</name>
            </script>
            <ambient>1 1 1 1</ambient>
            <diffuse>1 1 1 1</diffuse>
            <specular>0.2 0.2 0.2 1</specular>
            <emissive>0 0 0 1</emissive>
          </material>
          <meta>
            <layer>0</layer>
          </meta>
          <cast_shadows>1</cast_shadows>
          <transparency>0</transparency>
        </visual>
        <collision name='Wall_26_Collision'>
          <laser_retro>0</laser_retro>
          <max_contacts>10</max_contacts>
          <pose>0 0 0.5 0 -0 0</pose>
          <geometry>
            <box>
              <size>2 0.15 1</size>
            </box>
          </geometry>
          <surface>
            <friction>
              <ode>
                <mu>1</mu>
                <mu2>1</mu2>
                <fdir1>0 0 0</fdir1>
                <slip1>0</slip1>
                <slip2>0</slip2>
              </ode>
              <torsional>
                <coefficient>1</coefficient>
                <patch_radius>0</patch_radius>
                <surface_radius>0</surface_radius>
                <use_patch_radius>1</use_patch_radius>
                <ode>
                  <slip>0</slip>
                </ode>
              </torsional>
            </friction>
            <bounce>
              <restitution_coefficient>0</restitution_coefficient>
              <threshold>1e+06</threshold>
            </bounce>
            <contact>
              <collide_without_contact>0</collide_without_contact>
              <collide_without_contact_bitmask>1</collide_without_contact_bitmask>
              <collide_bitmask>1</collide_bitmask>
              <ode>
                <soft_cfm>0</soft_cfm>
                <soft_erp>0.2</soft_erp>
                <kp>1e+13</kp>
                <kd>1</kd>
                <max_vel>0.01</max_vel>
                <min_depth>0</min_depth>
              </ode>
              <bullet>
                <split_impulse>1</split_impulse>
                <split_impulse_penetration_threshold>-0.01</split_impulse_penetration_threshold>
                <soft_cfm>0</soft_cfm>
                <soft_erp>0.2</soft_erp>
                <kp>1e+13</kp>
                <kd>1</kd>
              </bullet>
            </contact>
          </surface>
        </collision>
        <gravity>1</gravity>
        <enable_wind>0</enable_wind>
      </link>
      <link name='Wall_28'>
        <pose>2.38813 -2.48047 0 0 -0 0</pose>
        <self_collide>0</self_collide>
        <kinematic>0</kinematic>
        <visual name='Wall_28_Visual'>
          <pose>0 0 0.5 0 -0 0</pose>
          <geometry>
            <box>
              <size>1.75 0.15 1</size>
            </box>
          </geometry>
          <material>
            <script>
              <uri>file://media/materials/scripts/gazebo.material</uri>
              <name>Gazebo/CeilingTiled</name>
            </script>
            <ambient>1 1 1 1</ambient>
            <diffuse>1 1 1 1</diffuse>
            <specular>0 0 0 1</specular>
            <emissive>0 0 0 1</emissive>
          </material>
          <meta>
            <layer>0</layer>
          </meta>
          <cast_shadows>1</cast_shadows>
          <transparency>0</transparency>
        </visual>
        <collision name='Wall_28_Collision'>
          <laser_retro>0</laser_retro>
          <max_contacts>10</max_contacts>
          <pose>0 0 0.5 0 -0 0</pose>
          <geometry>
            <box>
              <size>1.75 0.15 1</size>
            </box>
          </geometry>
          <surface>
            <friction>
              <ode>
                <mu>1</mu>
                <mu2>1</mu2>
                <fdir1>0 0 0</fdir1>
                <slip1>0</slip1>
                <slip2>0</slip2>
              </ode>
              <torsional>
                <coefficient>1</coefficient>
                <patch_radius>0</patch_radius>
                <surface_radius>0</surface_radius>
                <use_patch_radius>1</use_patch_radius>
                <ode>
                  <slip>0</slip>
                </ode>
              </torsional>
            </friction>
            <bounce>
              <restitution_coefficient>0</restitution_coefficient>
              <threshold>1e+06</threshold>
            </bounce>
            <contact>
              <collide_without_contact>0</collide_without_contact>
              <collide_without_contact_bitmask>1</collide_without_contact_bitmask>
              <collide_bitmask>1</collide_bitmask>
              <ode>
                <soft_cfm>0</soft_cfm>
                <soft_erp>0.2</soft_erp>
                <kp>1e+13</kp>
                <kd>1</kd>
                <max_vel>0.01</max_vel>
                <min_depth>0</min_depth>
              </ode>
              <bullet>
                <split_impulse>1</split_impulse>
                <split_impulse_penetration_threshold>-0.01</split_impulse_penetration_threshold>
                <soft_cfm>0</soft_cfm>
                <soft_erp>0.2</soft_erp>
                <kp>1e+13</kp>
                <kd>1</kd>
              </bullet>
            </contact>
          </surface>
        </collision>
        <gravity>1</gravity>
        <enable_wind>0</enable_wind>
      </link>
      <link name='Wall_29'>
        <pose>3.20562 -1.28798 0 0 -0 1.5708</pose>
        <self_collide>0</self_collide>
        <kinematic>0</kinematic>
        <visual name='Wall_29_Visual'>
          <pose>0 0 0.5 0 -0 0</pose>
          <geometry>
            <box>
              <size>2.5 0.15 1</size>
            </box>
          </geometry>
          <material>
            <script>
              <uri>file://media/materials/scripts/gazebo.material</uri>
              <name>Gazebo/CeilingTiled</name>
            </script>
            <ambient>1 1 1 1</ambient>
            <diffuse>1 1 1 1</diffuse>
            <specular>0 0 0 1</specular>
            <emissive>0 0 0 1</emissive>
          </material>
          <meta>
            <layer>0</layer>
          </meta>
          <cast_shadows>1</cast_shadows>
          <transparency>0</transparency>
        </visual>
        <collision name='Wall_29_Collision'>
          <laser_retro>0</laser_retro>
          <max_contacts>10</max_contacts>
          <pose>0 0 0.5 0 -0 0</pose>
          <geometry>
            <box>
              <size>2.5 0.15 1</size>
            </box>
          </geometry>
          <surface>
            <friction>
              <ode>
                <mu>1</mu>
                <mu2>1</mu2>
                <fdir1>0 0 0</fdir1>
                <slip1>0</slip1>
                <slip2>0</slip2>
              </ode>
              <torsional>
                <coefficient>1</coefficient>
                <patch_radius>0</patch_radius>
                <surface_radius>0</surface_radius>
                <use_patch_radius>1</use_patch_radius>
                <ode>
                  <slip>0</slip>
                </ode>
              </torsional>
            </friction>
            <bounce>
              <restitution_coefficient>0</restitution_coefficient>
              <threshold>1e+06</threshold>
            </bounce>
            <contact>
              <collide_without_contact>0</collide_without_contact>
              <collide_without_contact_bitmask>1</collide_without_contact_bitmask>
              <collide_bitmask>1</collide_bitmask>
              <ode>
                <soft_cfm>0</soft_cfm>
                <soft_erp>0.2</soft_erp>
                <kp>1e+13</kp>
                <kd>1</kd>
                <max_vel>0.01</max_vel>
                <min_depth>0</min_depth>
              </ode>
              <bullet>
                <split_impulse>1</split_impulse>
                <split_impulse_penetration_threshold>-0.01</split_impulse_penetration_threshold>
                <soft_cfm>0</soft_cfm>
                <soft_erp>0.2</soft_erp>
                <kp>1e+13</kp>
                <kd>1</kd>
              </bullet>
            </contact>
          </surface>
        </collision>
        <gravity>1</gravity>
        <enable_wind>0</enable_wind>
      </link>
      <link name='Wall_6'>
        <pose>0 5.425 0 0 -0 0</pose>
        <self_collide>0</self_collide>
        <kinematic>0</kinematic>
        <visual name='Wall_6_Visual'>
          <pose>0 0 1 0 -0 0</pose>
          <geometry>
            <box>
              <size>11 0.15 2</size>
            </box>
          </geometry>
          <material>
            <script>
              <uri>file://media/materials/scripts/gazebo.material</uri>
              <name>Gazebo/Wood</name>
            </script>
            <ambient>1 1 1 1</ambient>
            <diffuse>1 1 1 1</diffuse>
            <specular>0.2 0.2 0.2 1</specular>
            <emissive>0 0 0 1</emissive>
          </material>
          <meta>
            <layer>0</layer>
          </meta>
          <cast_shadows>1</cast_shadows>
          <transparency>0</transparency>
        </visual>
        <collision name='Wall_6_Collision'>
          <laser_retro>0</laser_retro>
          <max_contacts>10</max_contacts>
          <pose>0 0 1 0 -0 0</pose>
          <geometry>
            <box>
              <size>11 0.15 2</size>
            </box>
          </geometry>
          <surface>
            <friction>
              <ode>
                <mu>1</mu>
                <mu2>1</mu2>
                <fdir1>0 0 0</fdir1>
                <slip1>0</slip1>
                <slip2>0</slip2>
              </ode>
              <torsional>
                <coefficient>1</coefficient>
                <patch_radius>0</patch_radius>
                <surface_radius>0</surface_radius>
                <use_patch_radius>1</use_patch_radius>
                <ode>
                  <slip>0</slip>
                </ode>
              </torsional>
            </friction>
            <bounce>
              <restitution_coefficient>0</restitution_coefficient>
              <threshold>1e+06</threshold>
            </bounce>
            <contact>
              <collide_without_contact>0</collide_without_contact>
              <collide_without_contact_bitmask>1</collide_without_contact_bitmask>
              <collide_bitmask>1</collide_bitmask>
              <ode>
                <soft_cfm>0</soft_cfm>
                <soft_erp>0.2</soft_erp>
                <kp>1e+13</kp>
                <kd>1</kd>
                <max_vel>0.01</max_vel>
                <min_depth>0</min_depth>
              </ode>
              <bullet>
                <split_impulse>1</split_impulse>
                <split_impulse_penetration_threshold>-0.01</split_impulse_penetration_threshold>
                <soft_cfm>0</soft_cfm>
                <soft_erp>0.2</soft_erp>
                <kp>1e+13</kp>
                <kd>1</kd>
              </bullet>
            </contact>
          </surface>
        </collision>
        <gravity>1</gravity>
        <enable_wind>0</enable_wind>
      </link>
      <link name='Wall_7'>
        <pose>5.425 0 0 0 0 -1.5708</pose>
        <self_collide>0</self_collide>
        <kinematic>0</kinematic>
        <visual name='Wall_7_Visual'>
          <pose>0 0 1 0 -0 0</pose>
          <geometry>
            <box>
              <size>11 0.15 2</size>
            </box>
          </geometry>
          <material>
            <script>
              <uri>file://media/materials/scripts/gazebo.material</uri>
              <name>Gazebo/Wood</name>
            </script>
            <ambient>1 1 1 1</ambient>
            <diffuse>1 1 1 1</diffuse>
            <specular>0.2 0.2 0.2 1</specular>
            <emissive>0 0 0 1</emissive>
          </material>
          <meta>
            <layer>0</layer>
          </meta>
          <cast_shadows>1</cast_shadows>
          <transparency>0</transparency>
        </visual>
        <collision name='Wall_7_Collision'>
          <laser_retro>0</laser_retro>
          <max_contacts>10</max_contacts>
          <pose>0 0 1 0 -0 0</pose>
          <geometry>
            <box>
              <size>11 0.15 2</size>
            </box>
          </geometry>
          <surface>
            <friction>
              <ode>
                <mu>1</mu>
                <mu2>1</mu2>
                <fdir1>0 0 0</fdir1>
                <slip1>0</slip1>
                <slip2>0</slip2>
              </ode>
              <torsional>
                <coefficient>1</coefficient>
                <patch_radius>0</patch_radius>
                <surface_radius>0</surface_radius>
                <use_patch_radius>1</use_patch_radius>
                <ode>
                  <slip>0</slip>
                </ode>
              </torsional>
            </friction>
            <bounce>
              <restitution_coefficient>0</restitution_coefficient>
              <threshold>1e+06</threshold>
            </bounce>
            <contact>
              <collide_without_contact>0</collide_without_contact>
              <collide_without_contact_bitmask>1</collide_without_contact_bitmask>
              <collide_bitmask>1</collide_bitmask>
              <ode>
                <soft_cfm>0</soft_cfm>
                <soft_erp>0.2</soft_erp>
                <kp>1e+13</kp>
                <kd>1</kd>
                <max_vel>0.01</max_vel>
                <min_depth>0</min_depth>
              </ode>
              <bullet>
                <split_impulse>1</split_impulse>
                <split_impulse_penetration_threshold>-0.01</split_impulse_penetration_threshold>
                <soft_cfm>0</soft_cfm>
                <soft_erp>0.2</soft_erp>
                <kp>1e+13</kp>
                <kd>1</kd>
              </bullet>
            </contact>
          </surface>
        </collision>
        <gravity>1</gravity>
        <enable_wind>0</enable_wind>
      </link>
      <link name='Wall_8'>
        <pose>0 -5.425 0 0 -0 3.14159</pose>
        <self_collide>0</self_collide>
        <kinematic>0</kinematic>
        <visual name='Wall_8_Visual'>
          <pose>0 0 1 0 -0 0</pose>
          <geometry>
            <box>
              <size>11 0.15 2</size>
            </box>
          </geometry>
          <material>
            <script>
              <uri>file://media/materials/scripts/gazebo.material</uri>
              <name>Gazebo/Wood</name>
            </script>
            <ambient>1 1 1 1</ambient>
            <diffuse>1 1 1 1</diffuse>
            <specular>0.2 0.2 0.2 1</specular>
            <emissive>0 0 0 1</emissive>
          </material>
          <meta>
            <layer>0</layer>
          </meta>
          <cast_shadows>1</cast_shadows>
          <transparency>0</transparency>
        </visual>
        <collision name='Wall_8_Collision'>
          <laser_retro>0</laser_retro>
          <max_contacts>10</max_contacts>
          <pose>0 0 1 0 -0 0</pose>
          <geometry>
            <box>
              <size>11 0.15 2</size>
            </box>
          </geometry>
          <surface>
            <friction>
              <ode>
                <mu>1</mu>
                <mu2>1</mu2>
                <fdir1>0 0 0</fdir1>
                <slip1>0</slip1>
                <slip2>0</slip2>
              </ode>
              <torsional>
                <coefficient>1</coefficient>
                <patch_radius>0</patch_radius>
                <surface_radius>0</surface_radius>
                <use_patch_radius>1</use_patch_radius>
                <ode>
                  <slip>0</slip>
                </ode>
              </torsional>
            </friction>
            <bounce>
              <restitution_coefficient>0</restitution_coefficient>
              <threshold>1e+06</threshold>
            </bounce>
            <contact>
              <collide_without_contact>0</collide_without_contact>
              <collide_without_contact_bitmask>1</collide_without_contact_bitmask>
              <collide_bitmask>1</collide_bitmask>
              <ode>
                <soft_cfm>0</soft_cfm>
                <soft_erp>0.2</soft_erp>
                <kp>1e+13</kp>
                <kd>1</kd>
                <max_vel>0.01</max_vel>
                <min_depth>0</min_depth>
              </ode>
              <bullet>
                <split_impulse>1</split_impulse>
                <split_impulse_penetration_threshold>-0.01</split_impulse_penetration_threshold>
                <soft_cfm>0</soft_cfm>
                <soft_erp>0.2</soft_erp>
                <kp>1e+13</kp>
                <kd>1</kd>
              </bullet>
            </contact>
          </surface>
        </collision>
        <gravity>1</gravity>
        <enable_wind>0</enable_wind>
      </link>
      <link name='Wall_9'>
        <pose>-5.425 0 0 0 -0 1.5708</pose>
        <self_collide>0</self_collide>
        <kinematic>0</kinematic>
        <visual name='Wall_9_Visual'>
          <pose>0 0 1 0 -0 0</pose>
          <geometry>
            <box>
              <size>11 0.15 2</size>
            </box>
          </geometry>
          <material>
            <script>
              <uri>file://media/materials/scripts/gazebo.material</uri>
              <name>Gazebo/Wood</name>
            </script>
            <ambient>1 1 1 1</ambient>
            <diffuse>1 1 1 1</diffuse>
            <specular>0.2 0.2 0.2 1</specular>
            <emissive>0 0 0 1</emissive>
          </material>
          <meta>
            <layer>0</layer>
          </meta>
          <cast_shadows>1</cast_shadows>
          <transparency>0</transparency>
        </visual>
        <collision name='Wall_9_Collision'>
          <laser_retro>0</laser_retro>
          <max_contacts>10</max_contacts>
          <pose>0 0 1 0 -0 0</pose>
          <geometry>
            <box>
              <size>11 0.15 2</size>
            </box>
          </geometry>
          <surface>
            <friction>
              <ode>
                <mu>1</mu>
                <mu2>1</mu2>
                <fdir1>0 0 0</fdir1>
                <slip1>0</slip1>
                <slip2>0</slip2>
              </ode>
              <torsional>
                <coefficient>1</coefficient>
                <patch_radius>0</patch_radius>
                <surface_radius>0</surface_radius>
                <use_patch_radius>1</use_patch_radius>
                <ode>
                  <slip>0</slip>
                </ode>
              </torsional>
            </friction>
            <bounce>
              <restitution_coefficient>0</restitution_coefficient>
              <threshold>1e+06</threshold>
            </bounce>
            <contact>
              <collide_without_contact>0</collide_without_contact>
              <collide_without_contact_bitmask>1</collide_without_contact_bitmask>
              <collide_bitmask>1</collide_bitmask>
              <ode>
                <soft_cfm>0</soft_cfm>
                <soft_erp>0.2</soft_erp>
                <kp>1e+13</kp>
                <kd>1</kd>
                <max_vel>0.01</max_vel>
                <min_depth>0</min_depth>
              </ode>
              <bullet>
                <split_impulse>1</split_impulse>
                <split_impulse_penetration_threshold>-0.01</split_impulse_penetration_threshold>
                <soft_cfm>0</soft_cfm>
                <soft_erp>0.2</soft_erp>
                <kp>1e+13</kp>
                <kd>1</kd>
              </bullet>
            </contact>
          </surface>
        </collision>
        <gravity>1</gravity>
        <enable_wind>0</enable_wind>
      </link>
      <static>1</static>
      <allow_auto_disable>1</allow_auto_disable>
      <pose>0.000564 -0.000118 0 0 -0 0</pose>
    </model>
    <model name='table'>
      <static>1</static>
      <link name='link'>
        <collision name='surface'>
          <pose>0 0 1 0 -0 0</pose>
          <geometry>
            <box>
              <size>1.5 0.8 0.03</size>
            </box>
          </geometry>
          <surface>
            <friction>
              <ode>
                <mu>0.6</mu>
                <mu2>0.6</mu2>
              </ode>
              <torsional>
                <ode/>
              </torsional>
            </friction>
            <contact>
              <ode/>
            </contact>
            <bounce/>
          </surface>
          <max_contacts>10</max_contacts>
        </collision>
        <visual name='visual1'>
          <pose>0 0 1 0 -0 0</pose>
          <geometry>
            <box>
              <size>1.4 0.8 0.04</size>
            </box>
          </geometry>
          <material>
            <script>
              <uri>file://media/materials/scripts/gazebo.material</uri>
              <name>Gazebo/Black</name>
            </script>
          </material>
        </visual>
        <collision name='front_left_leg'>
          <pose>0.68 0.38 0.5 0 -0 0</pose>
          <geometry>
            <cylinder>
              <radius>0.02</radius>
              <length>1</length>
            </cylinder>
          </geometry>
          <max_contacts>10</max_contacts>
          <surface>
            <contact>
              <ode/>
            </contact>
            <bounce/>
            <friction>
              <torsional>
                <ode/>
              </torsional>
              <ode/>
            </friction>
          </surface>
        </collision>
        <visual name='front_left_leg'>
          <pose>0.68 0.38 0.5 0 -0 0</pose>
          <geometry>
            <cylinder>
              <radius>0.02</radius>
              <length>1</length>
            </cylinder>
          </geometry>
          <material>
            <script>
              <uri>file://media/materials/scripts/gazebo.material</uri>
              <name>Gazebo/Grey</name>
            </script>
          </material>
        </visual>
        <collision name='front_right_leg'>
          <pose>0.68 -0.38 0.5 0 -0 0</pose>
          <geometry>
            <cylinder>
              <radius>0.02</radius>
              <length>1</length>
            </cylinder>
          </geometry>
          <max_contacts>10</max_contacts>
          <surface>
            <contact>
              <ode/>
            </contact>
            <bounce/>
            <friction>
              <torsional>
                <ode/>
              </torsional>
              <ode/>
            </friction>
          </surface>
        </collision>
        <visual name='front_right_leg'>
          <pose>0.68 -0.38 0.5 0 -0 0</pose>
          <geometry>
            <cylinder>
              <radius>0.02</radius>
              <length>1</length>
            </cylinder>
          </geometry>
          <material>
            <script>
              <uri>file://media/materials/scripts/gazebo.material</uri>
              <name>Gazebo/Grey</name>
            </script>
          </material>
        </visual>
        <collision name='back_right_leg'>
          <pose>-0.68 -0.38 0.5 0 -0 0</pose>
          <geometry>
            <cylinder>
              <radius>0.02</radius>
              <length>1</length>
            </cylinder>
          </geometry>
          <max_contacts>10</max_contacts>
          <surface>
            <contact>
              <ode/>
            </contact>
            <bounce/>
            <friction>
              <torsional>
                <ode/>
              </torsional>
              <ode/>
            </friction>
          </surface>
        </collision>
        <visual name='back_right_leg'>
          <pose>-0.68 -0.38 0.5 0 -0 0</pose>
          <geometry>
            <cylinder>
              <radius>0.02</radius>
              <length>1</length>
            </cylinder>
          </geometry>
          <material>
            <script>
              <uri>file://media/materials/scripts/gazebo.material</uri>
              <name>Gazebo/Grey</name>
            </script>
          </material>
        </visual>
        <collision name='back_left_leg'>
          <pose>-0.68 0.38 0.5 0 -0 0</pose>
          <geometry>
            <cylinder>
              <radius>0.02</radius>
              <length>1</length>
            </cylinder>
          </geometry>
          <max_contacts>10</max_contacts>
          <surface>
            <contact>
              <ode/>
            </contact>
            <bounce/>
            <friction>
              <torsional>
                <ode/>
              </torsional>
              <ode/>
            </friction>
          </surface>
        </collision>
        <visual name='back_left_leg'>
          <pose>-0.68 0.38 0.5 0 -0 0</pose>
          <geometry>
            <cylinder>
              <radius>0.02</radius>
              <length>1</length>
            </cylinder>
          </geometry>
          <material>
            <script>
              <uri>file://media/materials/scripts/gazebo.material</uri>
              <name>Gazebo/Grey</name>
            </script>
          </material>
        </visual>
        <self_collide>0</self_collide>
        <inertial>
          <inertia>
            <ixx>1</ixx>
            <ixy>0</ixy>
            <ixz>0</ixz>
            <iyy>1</iyy>
            <iyz>0</iyz>
            <izz>1</izz>
          </inertia>
          <mass>1</mass>
          <pose>0 0 0 0 -0 0</pose>
        </inertial>
        <kinematic>0</kinematic>
        <gravity>1</gravity>
        <enable_wind>0</enable_wind>
      </link>
      <pose>-4.34248 -0.532954 0 0 -0 -1.57564</pose>
    </model>
    <model name='overhead_camera'>
      <static>1</static>
      <pose>0 0 8 3.14159 1.57079 3.14159</pose>
      <link name='link'>
        <visual name='visual'>
          <geometry>
            <box>
              <size>0.1 0.1 0.1</size>
            </box>
          </geometry>
        </visual>
        <sensor name='overhead_camera_sensor' type='camera'>
          <update_rate>5</update_rate>
          <camera name='overhead_cam'>
            <horizontal_fov>1.2</horizontal_fov>
            <image>
              <width>1024</width>
              <height>1024</height>
              <format>R8G8B8</format>
            </image>
            <clip>
              <near>0.1</near>
              <far>100</far>
            </clip>
          </camera>
          <plugin name='camera_controller' filename='libgazebo_ros_camera.so'>
            <alwaysOn>1</alwaysOn>
            <updateRate>5.0</updateRate>
            <cameraName>overhead_camera</cameraName>
            <imageTopicName>image_raw</imageTopicName>
            <frameName>overhead_camera_link</frameName>
          </plugin>
        </sensor>
        <self_collide>0</self_collide>
        <enable_wind>0</enable_wind>
        <kinematic>0</kinematic>
      </link>
    </model>
    <gui fullscreen='0'>
      <camera name='user_camera'>
        <pose>1.89423 -6.9588 20.2454 -0 1.2658 1.46351</pose>
        <view_controller>orbit</view_controller>
        <projection_type>perspective</projection_type>
      </camera>
    </gui>
    <wind/>
    <model name='postbox'>
      <static>1</static>
      <link name='link'>
        <collision name='collision'>
          <geometry>
            <mesh>
              <scale>0.8 0.8 0.8</scale>
              <uri>model://postbox/meshes/postbox.dae</uri>
            </mesh>
          </geometry>
          <max_contacts>10</max_contacts>
          <surface>
            <contact>
              <ode/>
            </contact>
            <bounce/>
            <friction>
              <torsional>
                <ode/>
              </torsional>
              <ode/>
            </friction>
          </surface>
        </collision>
        <visual name='visual'>
          <geometry>
            <mesh>
              <scale>0.8 0.8 0.8</scale>
              <uri>model://postbox/meshes/postbox.dae</uri>
            </mesh>
          </geometry>
        </visual>
        <self_collide>0</self_collide>
        <enable_wind>0</enable_wind>
        <kinematic>0</kinematic>
      </link>
      <pose>4.78576 4.93896 0 0 -0 0</pose>
    </model>
    <model name='person_standing'>
      <link name='link'>
        <inertial>
          <pose>0 -0.1 0.95 0 -0 0</pose>
          <mass>80</mass>
          <inertia>
            <ixx>24.88</ixx>
            <ixy>0</ixy>
            <ixz>0</ixz>
            <iyy>25.73</iyy>
            <iyz>0</iyz>
            <izz>2.48</izz>
          </inertia>
        </inertial>
        <collision name='bottom'>
          <pose>0 -0.1 0.01 0 -0 0</pose>
          <geometry>
            <box>
              <size>0.5 0.35 0.02</size>
            </box>
          </geometry>
          <max_contacts>10</max_contacts>
          <surface>
            <contact>
              <ode/>
            </contact>
            <bounce/>
            <friction>
              <torsional>
                <ode/>
              </torsional>
              <ode/>
            </friction>
          </surface>
        </collision>
        <collision name='person'>
          <pose>0 0 0.02 0.04 -0 0</pose>
          <geometry>
            <mesh>
              <uri>model://person_standing/meshes/standing.dae</uri>
              <scale>0.8 0.8 0.7</scale>
            </mesh>
          </geometry>
          <max_contacts>10</max_contacts>
          <surface>
            <contact>
              <ode/>
            </contact>
            <bounce/>
            <friction>
              <torsional>
                <ode/>
              </torsional>
              <ode/>
            </friction>
          </surface>
        </collision>
        <visual name='visual'>
          <pose>0 0 0.02 0.04 -0 0</pose>
          <geometry>
            <mesh>
              <uri>model://person_standing/meshes/standing.dae</uri>
              <scale>0.8 0.8 0.7</scale>
            </mesh>
          </geometry>
        </visual>
        <self_collide>0</self_collide>
        <enable_wind>0</enable_wind>
        <kinematic>0</kinematic>
      </link>
      <pose>-4.97896 5.23668 -0.003 -1e-06 -1e-06 0.000605</pose>
    </model>
    <model name='trash_can'>
      <link name='link'>
        <inertial>
          <pose>0 0 0.3683 0 -0 0</pose>
          <mass>4.83076</mass>
          <inertia>
            <ixx>0.281534</ixx>
            <ixy>0</ixy>
            <ixz>0</ixz>
            <iyy>0.281534</iyy>
            <iyz>0</iyz>
            <izz>0.126223</izz>
          </inertia>
        </inertial>
        <visual name='visual'>
          <geometry>
            <mesh>
              <uri>model://first_2015_trash_can/meshes/trash_can.dae</uri>
            </mesh>
          </geometry>
        </visual>
        <collision name='collision'>
          <geometry>
            <mesh>
              <uri>model://first_2015_trash_can/meshes/trash_can.dae</uri>
            </mesh>
          </geometry>
          <max_contacts>10</max_contacts>
          <surface>
            <contact>
              <ode/>
            </contact>
            <bounce/>
            <friction>
              <torsional>
                <ode/>
              </torsional>
              <ode/>
            </friction>
          </surface>
        </collision>
        <self_collide>0</self_collide>
        <enable_wind>0</enable_wind>
        <kinematic>0</kinematic>
      </link>
      <pose>-4.88103 -4.93535 0 0 -0 0</pose>
    </model>
    <state world_name='default'>
      <sim_time>2000 837000000</sim_time>
      <real_time>75 197612332</real_time>
      <wall_time>1773915214 952295083</wall_time>
      <iterations>75033</iterations>
      <model name='Construction Cone'>
        <pose>1.47437 2.06266 -0 0 -1e-06 0</pose>
        <scale>1 1 1</scale>
        <link name='link'>
          <pose>1.47437 2.06266 -0 0 -1e-06 0</pose>
          <velocity>0 0 0 0 -0 0</velocity>
          <acceleration>-0 0 0.008512 2.58585 -1.13682 -3.14159</acceleration>
          <wrench>-0 0 0.008512 0 -0 0</wrench>
        </link>
      </model>
      <model name='Construction Cone_clone'>
        <pose>4.86388 -1.28362 -5e-06 -4e-06 1e-06 0</pose>
        <scale>1 1 1</scale>
        <link name='link'>
          <pose>4.86388 -1.28362 -5e-06 -4e-06 1e-06 0</pose>
          <velocity>0 0 0 0 -0 0</velocity>
          <acceleration>0 0 -9.8 0 -0 0</acceleration>
          <wrench>0 0 -9.8 0 -0 0</wrench>
        </link>
      </model>
      <model name='Construction Cone_clone_0'>
        <pose>3.78125 2.05908 -0 0 -1e-06 0</pose>
        <scale>1 1 1</scale>
        <link name='link'>
          <pose>3.78125 2.05908 -0 0 -1e-06 0</pose>
          <velocity>0 0 0 0 -0 0</velocity>
          <acceleration>-0 0 0.008512 2.58585 -1.13682 -3.14159</acceleration>
          <wrench>-0 0 0.008512 0 -0 0</wrench>
        </link>
      </model>
      <model name='Construction Cone_clone_1'>
        <pose>3.03821 3.74159 -0 0 -0 0</pose>
        <scale>1 1 1</scale>
        <link name='link'>
          <pose>3.03821 3.74159 -0 0 -0 0</pose>
          <velocity>0 0 0 0 -0 0</velocity>
          <acceleration>0 -0 -0.008512 -2.58585 1.13682 3.14159</acceleration>
          <wrench>0 -0 -0.008512 0 -0 0</wrench>
        </link>
      </model>
      <model name='Construction Cone_clone_2'>
        <pose>-2.70216 4.04821 -9e-06 -5e-06 -0 -0</pose>
        <scale>1 1 1</scale>
        <link name='link'>
          <pose>-2.70216 4.04821 -9e-06 -5e-06 -0 -0</pose>
          <velocity>0 0 0 0 -0 0</velocity>
          <acceleration>0 0 -9.8 0 -0 0</acceleration>
          <wrench>0 0 -9.8 0 -0 0</wrench>
        </link>
      </model>
      <model name='Construction Cone_clone_3'>
        <pose>-3.84854 -3.14281 -4e-06 3e-06 -0 0</pose>
        <scale>1 1 1</scale>
        <link name='link'>
          <pose>-3.84854 -3.14281 -4e-06 3e-06 -0 0</pose>
          <velocity>0 0 0 0 -0 0</velocity>
          <acceleration>0 0 -9.8 0 -0 0</acceleration>
          <wrench>0 0 -9.8 0 -0 0</wrench>
        </link>
      </model>
      <model name='Construction Cone_clone_4'>
        <pose>-2.07238 -4.77459 -1e-05 0 -0 0</pose>
        <scale>1 1 1</scale>
        <link name='link'>
          <pose>-2.07238 -4.77459 -1e-05 0 -0 0</pose>
          <velocity>0 0 0 0 -0 0</velocity>
          <acceleration>0 0 -9.8 0 -0 0</acceleration>
          <wrench>0 0 -9.8 0 -0 0</wrench>
        </link>
      </model>
      <model name='Construction Cone_clone_5'>
        <pose>1.64855 -0.595661 -6e-06 2e-06 -0 0</pose>
        <scale>1 1 1</scale>
        <link name='link'>
          <pose>1.64855 -0.595661 -6e-06 2e-06 -0 0</pose>
          <velocity>0 0 0 0 -0 0</velocity>
          <acceleration>0 0 -9.8 0 -0 0</acceleration>
          <wrench>0 0 -9.8 0 -0 0</wrench>
        </link>
      </model>
      <model name='Construction Cone_clone_6'>
        <pose>-1.73672 0.238001 -0 0 -0 0</pose>
        <scale>1 1 1</scale>
        <link name='link'>
          <pose>-1.73672 0.238001 -0 0 -0 0</pose>
          <velocity>0 0 0 0 -0 0</velocity>
          <acceleration>0 -0 -0.008512 -2.58585 1.13682 3.14159</acceleration>
          <wrench>0 -0 -0.008512 0 -0 0</wrench>
        </link>
      </model>
      <model name='Fridge'>
        <pose>0.236502 4.94296 0 0 0 -1.56571</pose>
        <scale>1 1 1</scale>
        <link name='base_link'>
          <pose>0.236502 4.94296 0 0 0 -1.56571</pose>
          <velocity>0 0 0 0 -0 0</velocity>
          <acceleration>0 0 0 0 -0 0</acceleration>
          <wrench>0 0 0 0 -0 0</wrench>
        </link>
      </model>
      <model name='box'>
        <pose>0.00683 0.00059 0 0 -0 0</pose>
        <scale>1 1 1</scale>
        <link name='Wall_11'>
          <pose>-2.14517 1.85759 -0 0 -0 0</pose>
          <velocity>0 0 0 0 -0 0</velocity>
          <acceleration>0 0 0 0 -0 0</acceleration>
          <wrench>0 0 0 0 -0 0</wrench>
        </link>
        <link name='Wall_13'>
          <pose>-2.14817 1.76459 -0 0 0 -1.5708</pose>
          <velocity>0 0 0 0 -0 0</velocity>
          <acceleration>0 0 0 0 -0 0</acceleration>
          <wrench>0 0 0 0 -0 0</wrench>
        </link>
        <link name='Wall_15'>
          <pose>2.73083 3.02959 -0 0 -0 0</pose>
          <velocity>0 0 0 0 -0 0</velocity>
          <acceleration>0 0 0 0 -0 0</acceleration>
          <wrench>0 0 0 0 -0 0</wrench>
        </link>
        <link name='Wall_16'>
          <pose>3.29833 2.62209 -0 0 0 -1.54994</pose>
          <velocity>0 0 0 0 -0 0</velocity>
          <acceleration>0 0 0 0 -0 0</acceleration>
          <wrench>0 0 0 0 -0 0</wrench>
        </link>
        <link name='Wall_17'>
          <pose>2.75683 2.21459 -0 0 -0 3.14159</pose>
          <velocity>0 0 0 0 -0 0</velocity>
          <acceleration>0 0 0 0 -0 0</acceleration>
          <wrench>0 0 0 0 -0 0</wrench>
        </link>
        <link name='Wall_18'>
          <pose>2.18933 2.62209 -0 0 -0 1.61372</pose>
          <velocity>0 0 0 0 -0 0</velocity>
          <acceleration>0 0 0 0 -0 0</acceleration>
          <wrench>0 0 0 0 -0 0</wrench>
        </link>
        <link name='Wall_24'>
          <pose>-2.88893 -2.49029 -0 0 -0 1.09459</pose>
          <velocity>0 0 0 0 -0 0</velocity>
          <acceleration>0 0 0 0 -0 0</acceleration>
          <wrench>0 0 0 0 -0 0</wrench>
        </link>
        <link name='Wall_25'>
          <pose>-1.96394 -2.49029 -0 0 0 -1.01325</pose>
          <velocity>0 0 0 0 -0 0</velocity>
          <acceleration>0 0 0 0 -0 0</acceleration>
          <wrench>0 0 0 0 -0 0</wrench>
        </link>
        <link name='Wall_26'>
          <pose>-2.3827 -3.28468 -0 0 -0 3.14159</pose>
          <velocity>0 0 0 0 -0 0</velocity>
          <acceleration>0 0 0 0 -0 0</acceleration>
          <wrench>0 0 0 0 -0 0</wrench>
        </link>
        <link name='Wall_28'>
          <pose>2.39496 -2.47988 -0 0 -0 0</pose>
          <velocity>0 0 0 0 -0 0</velocity>
          <acceleration>0 0 0 0 -0 0</acceleration>
          <wrench>0 0 0 0 -0 0</wrench>
        </link>
        <link name='Wall_29'>
          <pose>3.21245 -1.28739 -0 0 -0 1.5708</pose>
          <velocity>0 0 0 0 -0 0</velocity>
          <acceleration>0 0 0 0 -0 0</acceleration>
          <wrench>0 0 0 0 -0 0</wrench>
        </link>
        <link name='Wall_6'>
          <pose>0.006831 5.42559 -0 0 -0 0</pose>
          <velocity>0 0 0 0 -0 0</velocity>
          <acceleration>0 0 0 0 -0 0</acceleration>
          <wrench>0 0 0 0 -0 0</wrench>
        </link>
        <link name='Wall_7'>
          <pose>5.43183 0.000587 -0 0 0 -1.5708</pose>
          <velocity>0 0 0 0 -0 0</velocity>
          <acceleration>0 0 0 0 -0 0</acceleration>
          <wrench>0 0 0 0 -0 0</wrench>
        </link>
        <link name='Wall_8'>
          <pose>0.006831 -5.42441 -0 0 -0 3.14159</pose>
          <velocity>0 0 0 0 -0 0</velocity>
          <acceleration>0 0 0 0 -0 0</acceleration>
          <wrench>0 0 0 0 -0 0</wrench>
        </link>
        <link name='Wall_9'>
          <pose>-5.41817 0.000587 -0 0 -0 1.5708</pose>
          <velocity>0 0 0 0 -0 0</velocity>
          <acceleration>0 0 0 0 -0 0</acceleration>
          <wrench>0 0 0 0 -0 0</wrench>
        </link>
      </model>
      <model name='drc_practice_blue_cylinder'>
        <pose>3.34628 -3.3055 0 0 -0 0</pose>
        <scale>1 1 1</scale>
        <link name='link'>
          <pose>3.34628 -3.3055 0 0 -0 0</pose>
          <velocity>0 0 0 0 -0 0</velocity>
          <acceleration>0 0 0 0 -0 0</acceleration>
          <wrench>0 0 0 0 -0 0</wrench>
        </link>
      </model>
      <model name='ground_plane'>
        <pose>0 0 0 0 -0 0</pose>
        <scale>1 1 1</scale>
        <link name='link'>
          <pose>0 0 0 0 -0 0</pose>
          <velocity>0 0 0 0 -0 0</velocity>
          <acceleration>0 0 0 0 -0 0</acceleration>
          <wrench>0 0 0 0 -0 0</wrench>
        </link>
      </model>
      <model name='guitar'>
        <pose>4.9814 -5.0624 0.021272 1.37668 0.069076 -2.98176</pose>
        <scale>1 1 1</scale>
        <link name='link'>
          <pose>4.9814 -5.0624 0.021272 1.37668 0.069076 -2.98176</pose>
          <velocity>0 0 0 0 -0 0</velocity>
          <acceleration>0 0 0 0 -0 0</acceleration>
          <wrench>0 0 0 0 -0 0</wrench>
        </link>
      </model>
      <model name='number6'>
        <pose>-3.42605 2.83365 0.4 0 -0 0</pose>
        <scale>1 1 1</scale>
        <link name='link'>
          <pose>-3.42605 2.83365 0.4 0 -0 0</pose>
          <velocity>0 0 0 0 -0 0</velocity>
          <acceleration>0 0 0 0 -0 0</acceleration>
          <wrench>0 0 0 0 -0 0</wrench>
        </link>
      </model>
      <model name='overhead_camera'>
        <pose>0 0 8 3.14159 1.57079 3.14159</pose>
        <scale>1 1 1</scale>
        <link name='link'>
          <pose>0 0 8 3.14159 1.57079 3.14159</pose>
          <velocity>0 0 0 0 -0 0</velocity>
          <acceleration>0 0 0 0 -0 0</acceleration>
          <wrench>0 0 0 0 -0 0</wrench>
        </link>
      </model>
      <model name='person_standing'>
        <pose>-4.97898 5.23668 -0.003 0 1e-06 0.000831</pose>
        <scale>0.8 0.8 0.7</scale>
        <link name='link'>
          <pose>-4.97898 5.23668 -0.003 0 1e-06 0.000831</pose>
          <velocity>0 0 0 0 -0 0</velocity>
          <acceleration>-1.67873 -1.16719 0.949929 -1.85086 -1.40371 -3.07706</acceleration>
          <wrench>-134.298 -93.375 75.9944 0 -0 0</wrench>
        </link>
      </model>
      <model name='postbox'>
        <pose>4.78576 4.93896 0 0 -0 0</pose>
        <scale>0.8 0.8 0.8</scale>
        <link name='link'>
          <pose>4.78576 4.93896 0 0 -0 0</pose>
          <velocity>0 0 0 0 -0 0</velocity>
          <acceleration>0 0 0 0 -0 0</acceleration>
          <wrench>0 0 0 0 -0 0</wrench>
        </link>
      </model>
      <model name='table'>
        <pose>-4.92677 -0.830741 -9e-06 0 0 -1.57564</pose>
        <scale>1 1 1</scale>
        <link name='link'>
          <pose>-4.92677 -0.830741 -9e-06 0 -0 -1.57564</pose>
          <velocity>0 0 0 0 -0 0</velocity>
          <acceleration>0 0 0 0 -0 0</acceleration>
          <wrench>0 0 0 0 -0 0</wrench>
        </link>
      </model>
      <model name='trash_can'>
        <pose>-4.87735 -4.93616 -3e-06 -0 8e-06 -0.018888</pose>
        <scale>1 1 1</scale>
        <link name='link'>
          <pose>-4.87735 -4.93616 -3e-06 -0 8e-06 -0.018888</pose>
          <velocity>0 0 0 0 -0 0</velocity>
          <acceleration>-1.53127 0.741265 -5.69969 1.12948 1.01532 -3.14144</acceleration>
          <wrench>-7.39718 3.58087 -27.5338 0 -0 0</wrench>
        </link>
      </model>
      <model name='youbot'>
        <pose>0.621436 -4.2933 0.083974 6e-06 2.4e-05 0.00281</pose>
        <scale>1 1 1</scale>
        <link name='arm_link_0'>
          <pose>0.764437 -4.2929 0.129968 1e-05 2.5e-05 0.002811</pose>
          <velocity>9e-05 -0.000387 -0.000465 0.003366 0.002834 0.00028</velocity>
          <acceleration>0.123039 -0.169021 1.01049 -1.49421 0.836147 -0.994046</acceleration>
          <wrench>0.103968 -0.142823 0.85386 0 -0 0</wrench>
        </link>
        <link name='arm_link_1'>
          <pose>0.788439 -4.29283 0.225968 -1.7e-05 -3.1e-05 2.96986</pose>
          <velocity>0.000249 -0.00074 -0.000487 0.00301 0.004009 -0.004051</velocity>
          <acceleration>0.204855 -0.226622 1.0619 0.175481 -0.090056 -0.631901</acceleration>
          <wrench>0.49411 -0.546612 2.5613 0 -0 0</wrench>
        </link>
        <link name='arm_link_2'>
          <pose>0.755924 -4.28719 0.244967 -7.1e-05 -1.13449 2.9699</pose>
          <velocity>0.000343 -0.000673 -0.000292 0.001388 0.003872 -0.00156</velocity>
          <acceleration>0.871359 -0.726036 1.44069 -2.62154 -0.1653 0.524735</acceleration>
          <wrench>1.00642 -0.838572 1.664 0 -0 0</wrench>
        </link>
        <link name='arm_link_3'>
          <pose>0.894338 -4.3112 0.310453 0.000503 1.4137 2.97034</pose>
          <velocity>0.000577 -0.001615 0.000793 0.003685 -0.022047 -0.002305</velocity>
          <acceleration>0.552857 -0.984356 -0.849165 0.549604 -1.39398 0.820866</acceleration>
          <wrench>0.516368 -0.919389 -0.79312 0 -0 0</wrench>
        </link>
        <link name='arm_link_4'>
          <pose>0.762964 -4.28841 0.331571 0.000114 -0.375273 2.9698</pose>
          <velocity>0.000118 -0.001326 -0.001828 0.005844 -0.021612 -0.002265</velocity>
          <acceleration>0.680846 -0.546701 -5.74201 2.19247 -0.404417 -1.23301</acceleration>
          <wrench>0.597102 -0.479457 -5.03574 0 -0 0</wrench>
        </link>
        <link name='arm_link_5'>
          <pose>0.811745 -4.29686 0.451793 -0.320395 0.198882 -1.20523</pose>
          <velocity>-0.003595 -0.002281 -0.000216 0.002941 0.000373 0.002797</velocity>
          <acceleration>-4.82148 -1.06203 -2.96765 1.30791 0.73465 -3.03667</acceleration>
          <wrench>-1.21019 -0.26657 -0.744881 0 -0 0</wrench>
        </link>
        <link name='base_footprint'>
          <pose>0.621436 -4.2933 0.083974 6e-06 2.4e-05 0.00281</pose>
          <velocity>-4e-06 -0.000131 -0.000204 0.003686 0.001877 -0.00065</velocity>
          <acceleration>0.000409 -0.087715 1.23723 0.614183 0.983393 0.14906</acceleration>
          <wrench>4.1e-05 -0.008771 0.123723 0 -0 0</wrench>
        </link>
        <link name='base_laser_front_link'>
          <pose>0.921434 -4.29246 0.053967 6e-06 2.4e-05 0.00281</pose>
          <velocity>-5.9e-05 -0.000215 -0.000763 0.003685 0.001873 -0.000663</velocity>
          <acceleration>0.02051 -0.051218 0.952049 0.606237 0.971401 0.123537</acceleration>
          <wrench>0.003282 -0.008195 0.152328 0 -0 0</wrench>
        </link>
        <link name='base_link'>
          <pose>0.621436 -4.2933 0.083974 6e-06 2.4e-05 0.00281</pose>
          <velocity>-4e-06 -0.000131 -0.000208 0.003689 0.001879 -0.000649</velocity>
          <acceleration>0.05095 -0.119213 1.23331 0.622527 0.994349 0.150022</acceleration>
          <wrench>1.12089 -2.62268 27.1328 0 -0 0</wrench>
        </link>
        <link name='caster_link_bl'>
          <pose>0.392992 -4.13594 0.050001 6e-06 2.4e-05 0.002846</pose>
          <velocity>6.4e-05 -4.4e-05 0.000242 0.003603 0.001872 -0.000166</velocity>
          <acceleration>-0.035727 -0.069402 -0.208425 0.616011 0.970265 -0.093171</acceleration>
          <wrench>-0.003573 -0.00694 -0.020842 0 -0 0</wrench>
        </link>
        <link name='caster_link_br'>
          <pose>0.39388 -4.45194 0.049998 6e-06 2.4e-05 0.004604</pose>
          <velocity>-0.000168 -4.6e-05 0.000412 0.003632 0.001875 -0.000344</velocity>
          <acceleration>-0.045385 -0.070558 -0.165369 0.629289 0.979969 -0.128174</acceleration>
          <wrench>-0.004539 -0.007056 -0.016537 0 -0 0</wrench>
        </link>
        <link name='caster_link_fl'>
          <pose>0.84899 -4.13466 0.049999 7e-06 2.3e-05 0.010127</pose>
          <velocity>6.7e-05 -0.00017 0.000527 0.003703 0.001872 -0.000151</velocity>
          <acceleration>-0.036752 -0.043275 -0.136653 0.612355 0.988733 -0.085744</acceleration>
          <wrench>-0.003675 -0.004328 -0.013665 0 -0 0</wrench>
        </link>
        <link name='caster_link_fr'>
          <pose>0.849878 -4.45066 0.049994 7e-06 2.4e-05 0.013</pose>
          <velocity>-0.000121 -0.000174 0.000693 0.003726 0.001875 -0.000252</velocity>
          <acceleration>0.082988 -0.048308 9.3628 0.807654 0.985154 -0.134291</acceleration>
          <wrench>0.008299 -0.004831 0.93628 0 -0 0</wrench>
        </link>
        <link name='gripper_finger_link_l'>
          <pose>0.84661 -4.29565 0.48778 0.320393 -0.19888 1.93637</pose>
          <velocity>-0.004328 -0.00242 0.000104 8.8e-05 -0.005026 -0.000905</velocity>
          <acceleration>-6.16747 -1.36952 -2.08834 -2.18986 -0.1015 -2.8477</acceleration>
          <wrench>-0.061675 -0.013695 -0.020883 0 -0 0</wrench>
        </link>
        <link name='gripper_finger_link_r'>
          <pose>0.822846 -4.30658 0.496271 -0.320393 0.198879 -1.20523</pose>
          <velocity>-0.004378 -0.00239 -2.4e-05 0.00012 -0.005324 -0.000937</velocity>
          <acceleration>-6.3954 -1.33018 -2.61446 -2.24093 -0.354889 -2.84485</acceleration>
          <wrench>-0.063954 -0.013302 -0.026145 0 -0 0</wrench>
        </link>
        <link name='gripper_palm_link'>
          <pose>0.811745 -4.29686 0.451793 -0.320393 0.198879 -1.20523</pose>
          <velocity>-0.004106 -0.002374 -7.3e-05 7.3e-05 -0.004888 -0.00089</velocity>
          <acceleration>-5.49182 -1.13448 -2.76727 -2.16683 0.014786 -2.8488</acceleration>
          <wrench>-0.549182 -0.113448 -0.276727 0 -0 0</wrench>
        </link>
        <link name='plate_link'>
          <pose>0.462438 -4.29375 0.129977 6e-06 2.4e-05 0.00281</pose>
          <velocity>8.2e-05 -0.000195 7.8e-05 0.003697 0.001885 -0.000658</velocity>
          <acceleration>0.097631 -0.171221 1.38266 0.644003 1.02543 0.13862</acceleration>
          <wrench>0.097631 -0.171221 1.38266 0 -0 0</wrench>
        </link>
        <link name='wheel_link_bl'>
          <pose>0.392992 -4.13594 0.05 6e-06 -0.133268 0.002845</pose>
          <velocity>8.1e-05 -0.000163 0.000268 0.003328 0.001633 -0.000153</velocity>
          <acceleration>-0.049868 -0.033518 -0.119928 0.676103 -0.997035 -0.103446</acceleration>
          <wrench>-0.019947 -0.013407 -0.047971 0 -0 0</wrench>
        </link>
        <link name='wheel_link_br'>
          <pose>0.39388 -4.45194 0.049997 6e-06 -0.107208 0.004603</pose>
          <velocity>-0.000164 -0.000166 0.000364 0.003397 -0.003261 -0.00033</velocity>
          <acceleration>-0.091831 -0.034831 -0.087048 -2.44158 -1.29249 3.00272</acceleration>
          <wrench>-0.036732 -0.013932 -0.034819 0 -0 0</wrench>
        </link>
        <link name='wheel_link_fl'>
          <pose>0.84899 -4.13466 0.049997 7e-06 0.081875 0.010128</pose>
          <velocity>8.5e-05 -0.000182 0.000494 0.00368 0.001713 -0.000153</velocity>
          <acceleration>-0.051787 -0.031517 -0.074463 0.620016 -1.03557 -0.075468</acceleration>
          <wrench>-0.020715 -0.012607 -0.029785 0 -0 0</wrench>
        </link>
        <link name='wheel_link_fr'>
          <pose>0.849878 -4.45066 0.049993 8e-06 0.120298 0.013001</pose>
          <velocity>-8.9e-05 -0.000188 0.000579 0.00376 -0.001753 -0.000256</velocity>
          <acceleration>0.115525 -0.039043 8.84414 -2.19282 -0.563533 3.02334</acceleration>
          <wrench>0.04621 -0.015617 3.53765 0 -0 0</wrench>
        </link>
      </model>
      <light name='sun'>
        <pose>0 0 10 0 -0 0</pose>
      </light>
      <light name='user_point_light_0'>
        <pose>0 0 4.91465 0 -0 0</pose>
      </light>
    </state>
    <model name='Fridge'>
      <static>1</static>
      <link name='base_link'>
        <visual name='visual'>
          <geometry>
            <mesh>
              <uri>model://refrigirator/meshes/fridge.dae</uri>
            </mesh>
          </geometry>
          <material>
            <script>
              <uri>model://refrigirator/materials/scripts</uri>
              <uri>model://refrigirator/materials/textures</uri>
              <name>Fridge/Body</name>
            </script>
          </material>
        </visual>
        <collision name='Box001'>
          <pose>0 0 0.867923 0 -0 0</pose>
          <geometry>
            <box>
              <size>0.734673 0.7239 1.73585</size>
            </box>
          </geometry>
          <max_contacts>10</max_contacts>
          <surface>
            <contact>
              <ode/>
            </contact>
            <bounce/>
            <friction>
              <torsional>
                <ode/>
              </torsional>
              <ode/>
            </friction>
          </surface>
        </collision>
        <self_collide>0</self_collide>
        <enable_wind>0</enable_wind>
        <kinematic>0</kinematic>
      </link>
      <pose>0.237265 4.90714 0 0 -0 -1.5708</pose>
    </model>
    <light name='user_point_light_0' type='point'>
      <pose>0 0 1 0 -0 0</pose>
      <diffuse>0.5 0.5 0.5 1</diffuse>
      <specular>0.1 0.1 0.1 1</specular>
      <attenuation>
        <range>20</range>
        <constant>0.5</constant>
        <linear>0.01</linear>
        <quadratic>0.001</quadratic>
      </attenuation>
      <cast_shadows>0</cast_shadows>
      <direction>0 0 -1</direction>
      <spot>
        <inner_angle>0</inner_angle>
        <outer_angle>0</outer_angle>
        <falloff>0</falloff>
      </spot>
    </light>
    <model name='guitar'>
      <static>1</static>
      <link name='link'>
        <visual name='visual'>
          <geometry>
            <mesh>
              <uri>model://guitar/meshes/model.dae</uri>
              <scale>0.015 0.015 0.015</scale>
            </mesh>
          </geometry>
          <material>
            <script>
              <uri>model://guitar/materials/scripts</uri>
              <uri>model://guitar/materials/textures</uri>
              <name>Guitar/Body</name>
            </script>
          </material>
        </visual>
        <collision name='collision'>
          <geometry>
            <mesh>
              <uri>model://guitar/meshes/model.dae</uri>
              <scale>0.015 0.015 0.015</scale>
            </mesh>
          </geometry>
          <max_contacts>10</max_contacts>
          <surface>
            <contact>
              <ode/>
            </contact>
            <bounce/>
            <friction>
              <torsional>
                <ode/>
              </torsional>
              <ode/>
            </friction>
          </surface>
        </collision>
        <self_collide>0</self_collide>
        <enable_wind>0</enable_wind>
        <kinematic>0</kinematic>
      </link>
      <pose>4.9814 -5.0624 0.021272 1.37668 0.069076 -2.98176</pose>
    </model>
    <model name='youbot'>
      <pose>0.625746 -4.29274 0.09 0 -0 0</pose>
      <link name='base_footprint'>
        <pose>0 0 0 0 -0 0</pose>
        <inertial>
          <pose>0 0 -0.05 0 -0 0</pose>
          <inertia>
            <ixx>1</ixx>
            <ixy>0</ixy>
            <ixz>0</ixz>
            <iyy>1</iyy>
            <iyz>0</iyz>
            <izz>1</izz>
          </inertia>
          <mass>0.1</mass>
        </inertial>
        <collision name='base_footprint_geom'>
          <pose>0 0 -0.05 0 -0 0</pose>
          <geometry>
            <box>
              <size>0.001 0.001 0.001</size>
            </box>
          </geometry>
          <surface>
            <friction>
              <ode>
                <mu>0</mu>
                <mu2>0</mu2>
                <fdir1>0 0 0</fdir1>
                <slip1>0</slip1>
                <slip2>0</slip2>
              </ode>
              <torsional>
                <ode/>
              </torsional>
            </friction>
            <bounce>
              <restitution_coefficient>0</restitution_coefficient>
              <threshold>0</threshold>
            </bounce>
            <contact>
              <ode>
                <soft_cfm>0</soft_cfm>
                <soft_erp>0.2</soft_erp>
                <kp>1e+13</kp>
                <kd>1e+11</kd>
                <max_vel>-1</max_vel>
                <min_depth>0</min_depth>
              </ode>
            </contact>
          </surface>
          <laser_retro>0</laser_retro>
          <max_contacts>10</max_contacts>
        </collision>
        <visual name='base_footprint_geom_visual'>
          <pose>0 0 0 0 -0 0</pose>
          <geometry>
            <box>
              <size>0.001 0.001 0.001</size>
            </box>
          </geometry>
        </visual>
        <gravity>1</gravity>
        <self_collide>0</self_collide>
        <kinematic>0</kinematic>
        <enable_wind>0</enable_wind>
      </link>
      <link name='base_link'>
        <pose>0 0 0 0 -0 0</pose>
        <inertial>
          <pose>0 0 0 0 -0 0</pose>
          <inertia>
            <ixx>5.65223</ixx>
            <ixy>-0.00972</ixy>
            <ixz>1.29399</ixz>
            <iyy>5.66947</iyy>
            <iyz>-0.00738</iyz>
            <izz>3.6832</izz>
          </inertia>
          <mass>22</mass>
        </inertial>
        <collision name='base_link_geom'>
          <pose>0 0 0 0 -0 0</pose>
          <geometry>
            <mesh>
              <uri>model://youbot/meshes/base/base_convex.stl</uri>
            </mesh>
          </geometry>
          <surface>
            <friction>
              <ode>
                <mu>0</mu>
                <mu2>0</mu2>
                <fdir1>0 0 0</fdir1>
                <slip1>0</slip1>
                <slip2>0</slip2>
              </ode>
              <torsional>
                <ode/>
              </torsional>
            </friction>
            <bounce>
              <restitution_coefficient>0</restitution_coefficient>
              <threshold>0</threshold>
            </bounce>
            <contact>
              <ode>
                <soft_cfm>0</soft_cfm>
                <soft_erp>0.2</soft_erp>
                <kp>1e+13</kp>
                <kd>1e+11</kd>
                <max_vel>-1</max_vel>
                <min_depth>0</min_depth>
              </ode>
            </contact>
          </surface>
          <laser_retro>0</laser_retro>
          <max_contacts>10</max_contacts>
        </collision>
        <visual name='base_link_geom_visual'>
          <pose>0 0 0 0 -0 0</pose>
          <geometry>
            <mesh>
              <uri>model://youbot/meshes/base/base.dae</uri>
            </mesh>
          </geometry>
        </visual>
        <gravity>1</gravity>
        <self_collide>0</self_collide>
        <kinematic>0</kinematic>
        <enable_wind>0</enable_wind>
      </link>
      <link name='arm_link_0'>
        <pose>0.143 0 0.046 0 -0 0</pose>
        <inertial>
          <pose>0 0 0 0 -0 0</pose>
          <inertia>
            <ixx>0.01</ixx>
            <ixy>0</ixy>
            <ixz>0</ixz>
            <iyy>0.01</iyy>
            <iyz>0</iyz>
            <izz>0.01</izz>
          </inertia>
          <mass>0.845</mass>
        </inertial>
        <collision name='arm_link_0_geom'>
          <pose>0 0 0 0 -0 0</pose>
          <geometry>
            <mesh>
              <uri>model://youbot/meshes/arm/arm0_convex.stl</uri>
            </mesh>
          </geometry>
          <surface>
            <friction>
              <ode>
                <mu>0</mu>
                <mu2>0</mu2>
                <fdir1>0 0 0</fdir1>
                <slip1>0</slip1>
                <slip2>0</slip2>
              </ode>
              <torsional>
                <ode/>
              </torsional>
            </friction>
            <bounce>
              <restitution_coefficient>0</restitution_coefficient>
              <threshold>0</threshold>
            </bounce>
            <contact>
              <ode>
                <soft_cfm>0</soft_cfm>
                <soft_erp>0.2</soft_erp>
                <kp>1e+13</kp>
                <kd>1e+11</kd>
                <max_vel>-1</max_vel>
                <min_depth>0</min_depth>
              </ode>
            </contact>
          </surface>
          <laser_retro>0</laser_retro>
          <max_contacts>10</max_contacts>
        </collision>
        <visual name='arm_link_0_geom_visual'>
          <pose>0 0 0 0 -0 0</pose>
          <geometry>
            <mesh>
              <uri>model://youbot/meshes/arm/arm0.dae</uri>
            </mesh>
          </geometry>
          <material>
            <script>
              <uri>model://youbot/materials/scripts/youbot.material</uri>
              <name>youbot/DarkGrey</name>
            </script>
          </material>
        </visual>
        <gravity>1</gravity>
        <self_collide>0</self_collide>
        <kinematic>0</kinematic>
        <enable_wind>0</enable_wind>
      </link>
      <link name='arm_link_1'>
        <pose>0.167 0 0.142 0 -0 2.96706</pose>
        <inertial>
          <pose>0.01489 0.00213 0.00213 0 -0 0</pose>
          <inertia>
            <ixx>0.003863</ixx>
            <ixy>-0.000979</ixy>
            <ixz>0</ixz>
            <iyy>0.006196</iyy>
            <iyz>0</iyz>
            <izz>0.006369</izz>
          </inertia>
          <mass>2.412</mass>
        </inertial>
        <collision name='arm_link_1_geom'>
          <pose>0 0 0 0 -0 0</pose>
          <geometry>
            <mesh>
              <uri>model://youbot/meshes/arm/arm1_convex.stl</uri>
            </mesh>
          </geometry>
          <surface>
            <friction>
              <ode>
                <mu>0</mu>
                <mu2>0</mu2>
                <fdir1>0 0 0</fdir1>
                <slip1>0</slip1>
                <slip2>0</slip2>
              </ode>
              <torsional>
                <ode/>
              </torsional>
            </friction>
            <bounce>
              <restitution_coefficient>0</restitution_coefficient>
              <threshold>0</threshold>
            </bounce>
            <contact>
              <ode>
                <soft_cfm>0</soft_cfm>
                <soft_erp>0.2</soft_erp>
                <kp>1e+13</kp>
                <kd>1e+11</kd>
                <max_vel>-1</max_vel>
                <min_depth>0</min_depth>
              </ode>
            </contact>
          </surface>
          <laser_retro>0</laser_retro>
          <max_contacts>10</max_contacts>
        </collision>
        <visual name='arm_link_1_geom_visual'>
          <pose>0 0 0 0 -0 0</pose>
          <geometry>
            <mesh>
              <uri>model://youbot/meshes/arm/arm1.dae</uri>
            </mesh>
          </geometry>
        </visual>
        <gravity>1</gravity>
        <self_collide>0</self_collide>
        <kinematic>0</kinematic>
        <enable_wind>0</enable_wind>
      </link>
      <link name='arm_link_2'>
        <pose>0.134501 0.00573 0.161 0 -1.13446 2.96706</pose>
        <inertial>
          <pose>0.10453 0.0017 -0.00297 0 -0 0</pose>
          <inertia>
            <ixx>0.000823</ixx>
            <ixy>0</ixy>
            <ixz>-0</ixz>
            <iyy>0.004447</iyy>
            <iyz>0</iyz>
            <izz>0.004439</izz>
          </inertia>
          <mass>1.155</mass>
        </inertial>
        <collision name='arm_link_2_geom'>
          <pose>0 -0.032 0.078 0 -0 0</pose>
          <geometry>
            <mesh>
              <uri>model://youbot/meshes/arm/arm2_convex.stl</uri>
            </mesh>
          </geometry>
          <surface>
            <friction>
              <ode>
                <mu>0</mu>
                <mu2>0</mu2>
                <fdir1>0 0 0</fdir1>
                <slip1>0</slip1>
                <slip2>0</slip2>
              </ode>
              <torsional>
                <ode/>
              </torsional>
            </friction>
            <bounce>
              <restitution_coefficient>0</restitution_coefficient>
              <threshold>0</threshold>
            </bounce>
            <contact>
              <ode>
                <soft_cfm>0</soft_cfm>
                <soft_erp>0.2</soft_erp>
                <kp>1e+13</kp>
                <kd>1e+11</kd>
                <max_vel>-1</max_vel>
                <min_depth>0</min_depth>
              </ode>
            </contact>
          </surface>
          <laser_retro>0</laser_retro>
          <max_contacts>10</max_contacts>
        </collision>
        <visual name='arm_link_2_geom_visual'>
          <pose>0 -0.032 0.078 0 -0 0</pose>
          <geometry>
            <mesh>
              <uri>model://youbot/meshes/arm/arm2.dae</uri>
            </mesh>
          </geometry>
        </visual>
        <gravity>1</gravity>
        <self_collide>0</self_collide>
        <kinematic>0</kinematic>
        <enable_wind>0</enable_wind>
      </link>
      <link name='arm_link_3'>
        <pose>0.272845 -0.018663 0.226506 -0 1.41372 2.96706</pose>
        <inertial>
          <pose>0.0001 0.0967 0.02107 0 -0 0</pose>
          <inertia>
            <ixx>0.002459</ixx>
            <ixy>0</ixy>
            <ixz>0</ixz>
            <iyy>0.002571</iyy>
            <iyz>-0</iyz>
            <izz>0.000535</izz>
          </inertia>
          <mass>0.934</mass>
        </inertial>
        <collision name='arm_link_3_geom'>
          <pose>0 0.028 0.079 0 -0 0</pose>
          <geometry>
            <mesh>
              <uri>model://youbot/meshes/arm/arm3_convex.stl</uri>
            </mesh>
          </geometry>
          <surface>
            <friction>
              <ode>
                <mu>0</mu>
                <mu2>0</mu2>
                <fdir1>0 0 0</fdir1>
                <slip1>0</slip1>
                <slip2>0</slip2>
              </ode>
              <torsional>
                <ode/>
              </torsional>
            </friction>
            <bounce>
              <restitution_coefficient>0</restitution_coefficient>
              <threshold>0</threshold>
            </bounce>
            <contact>
              <ode>
                <soft_cfm>0</soft_cfm>
                <soft_erp>0.2</soft_erp>
                <kp>1e+13</kp>
                <kd>1e+11</kd>
                <max_vel>-1</max_vel>
                <min_depth>0</min_depth>
              </ode>
            </contact>
          </surface>
          <laser_retro>0</laser_retro>
          <max_contacts>10</max_contacts>
        </collision>
        <visual name='arm_link_3_geom_visual'>
          <pose>0 0.028 0.079 0 -0 0</pose>
          <geometry>
            <mesh>
              <uri>model://youbot/meshes/arm/arm3.dae</uri>
            </mesh>
          </geometry>
        </visual>
        <gravity>1</gravity>
        <self_collide>0</self_collide>
        <kinematic>0</kinematic>
        <enable_wind>0</enable_wind>
      </link>
      <link name='arm_link_4'>
        <pose>0.141533 0.004491 0.247624 0 -0.375246 2.96706</pose>
        <inertial>
          <pose>0.00011 0.05103 -0.02319 0 -0 0</pose>
          <inertia>
            <ixx>0.000869</ixx>
            <ixy>0</ixy>
            <ixz>-0</ixz>
            <iyy>0.001173</iyy>
            <iyz>-0.000231</iyz>
            <izz>0.001091</izz>
          </inertia>
          <mass>0.877</mass>
        </inertial>
        <collision name='arm_link_4_geom'>
          <pose>0 -0.01 0.029 0 -0 0</pose>
          <geometry>
            <mesh>
              <uri>model://youbot/meshes/arm/arm4_convex.stl</uri>
            </mesh>
          </geometry>
          <surface>
            <friction>
              <ode>
                <mu>0</mu>
                <mu2>0</mu2>
                <fdir1>0 0 0</fdir1>
                <slip1>0</slip1>
                <slip2>0</slip2>
              </ode>
              <torsional>
                <ode/>
              </torsional>
            </friction>
            <bounce>
              <restitution_coefficient>0</restitution_coefficient>
              <threshold>0</threshold>
            </bounce>
            <contact>
              <ode>
                <soft_cfm>0</soft_cfm>
                <soft_erp>0.2</soft_erp>
                <kp>1e+13</kp>
                <kd>1e+11</kd>
                <max_vel>-1</max_vel>
                <min_depth>0</min_depth>
              </ode>
            </contact>
          </surface>
          <laser_retro>0</laser_retro>
          <max_contacts>10</max_contacts>
        </collision>
        <visual name='arm_link_4_geom_visual'>
          <pose>0 -0.01 0.029 0 -0 0</pose>
          <geometry>
            <mesh>
              <uri>model://youbot/meshes/arm/arm4.dae</uri>
            </mesh>
          </geometry>
        </visual>
        <gravity>1</gravity>
        <self_collide>0</self_collide>
        <kinematic>0</kinematic>
        <enable_wind>0</enable_wind>
      </link>
      <link name='arm_link_5'>
        <pose>0.190287 -0.004106 0.367846 -0.085052 0.365926 -0.408445</pose>
        <inertial>
          <pose>0 0.00115 -0.01683 0 -0 0</pose>
          <inertia>
            <ixx>0.00028</ixx>
            <ixy>0</ixy>
            <ixz>0</ixz>
            <iyy>0.000339</iyy>
            <iyz>0</iyz>
            <izz>0.000119</izz>
          </inertia>
          <mass>0.251</mass>
        </inertial>
        <collision name='arm_link_5_geom'>
          <pose>0.003 0 -0.034 0 -0 0</pose>
          <geometry>
            <mesh>
              <uri>model://youbot/meshes/arm/arm5_convex.stl</uri>
            </mesh>
          </geometry>
          <surface>
            <bounce>
              <restitution_coefficient>0</restitution_coefficient>
              <threshold>0</threshold>
            </bounce>
            <contact>
              <ode>
                <soft_cfm>0</soft_cfm>
                <soft_erp>0.2</soft_erp>
                <kp>1e+13</kp>
                <kd>1e+11</kd>
                <max_vel>-1</max_vel>
                <min_depth>0</min_depth>
              </ode>
            </contact>
            <friction>
              <torsional>
                <ode/>
              </torsional>
              <ode/>
            </friction>
          </surface>
          <laser_retro>0</laser_retro>
          <max_contacts>10</max_contacts>
        </collision>
        <visual name='arm_link_5_geom_visual'>
          <pose>0.003 0 -0.034 0 -0 0</pose>
          <geometry>
            <mesh>
              <uri>model://youbot/meshes/arm/arm5.dae</uri>
            </mesh>
          </geometry>
        </visual>
        <gravity>1</gravity>
        <self_collide>0</self_collide>
        <kinematic>0</kinematic>
        <enable_wind>0</enable_wind>
      </link>
      <link name='gripper_palm_link'>
        <pose>0.190287 -0.004106 0.367846 -0.085052 0.365926 -0.408445</pose>
        <inertial>
          <pose>0 0 0 0 -0 0</pose>
          <inertia>
            <ixx>0.01</ixx>
            <ixy>0</ixy>
            <ixz>0</ixz>
            <iyy>0.01</iyy>
            <iyz>0</iyz>
            <izz>0.01</izz>
          </inertia>
          <mass>0.1</mass>
        </inertial>
        <collision name='gripper_palm_link_geom'>
          <pose>0 0 0 0 -0 0</pose>
          <geometry>
            <mesh>
              <uri>model://youbot/meshes/gripper/palm_convex.stl</uri>
            </mesh>
          </geometry>
          <surface>
            <friction>
              <ode>
                <mu>0</mu>
                <mu2>0</mu2>
                <fdir1>0 0 0</fdir1>
                <slip1>0</slip1>
                <slip2>0</slip2>
              </ode>
              <torsional>
                <ode/>
              </torsional>
            </friction>
            <bounce>
              <restitution_coefficient>0</restitution_coefficient>
              <threshold>0</threshold>
            </bounce>
            <contact>
              <ode>
                <soft_cfm>0</soft_cfm>
                <soft_erp>0.2</soft_erp>
                <kp>1e+13</kp>
                <kd>1e+11</kd>
                <max_vel>-1</max_vel>
                <min_depth>0</min_depth>
              </ode>
            </contact>
          </surface>
          <laser_retro>0</laser_retro>
          <max_contacts>10</max_contacts>
        </collision>
        <visual name='gripper_palm_link_geom_visual'>
          <pose>0 0 0 0 -0 0</pose>
          <geometry>
            <mesh>
              <uri>model://youbot/meshes/gripper/palm.stl</uri>
            </mesh>
          </geometry>
          <material>
            <script>
              <uri>file://media/materials/scripts/gazebo.material</uri>
              <name>Gazebo/Black</name>
            </script>
          </material>
        </visual>
        <gravity>1</gravity>
        <self_collide>1</self_collide>
        <kinematic>0</kinematic>
        <enable_wind>0</enable_wind>
      </link>
      <link name='gripper_finger_link_l'>
        <pose>0.21326 -0.001105 0.408579 0.085052 -0.365926 2.73315</pose>
        <inertial>
          <pose>0 -0.001 0 0 -0 0</pose>
          <inertia>
            <ixx>0.01</ixx>
            <ixy>0</ixy>
            <ixz>0</ixz>
            <iyy>0.01</iyy>
            <iyz>0</iyz>
            <izz>0.01</izz>
          </inertia>
          <mass>0.01</mass>
        </inertial>
        <collision name='gripper_finger_link_l_geom'>
          <pose>0 0 0 0 -0 0</pose>
          <geometry>
            <mesh>
              <uri>model://youbot/meshes/gripper/finger_convex.stl</uri>
            </mesh>
          </geometry>
          <surface>
            <bounce>
              <restitution_coefficient>0</restitution_coefficient>
              <threshold>0</threshold>
            </bounce>
            <contact>
              <ode>
                <soft_cfm>0</soft_cfm>
                <soft_erp>0.2</soft_erp>
                <kp>1e+13</kp>
                <kd>1e+11</kd>
                <max_vel>-1</max_vel>
                <min_depth>0</min_depth>
              </ode>
            </contact>
            <friction>
              <torsional>
                <ode/>
              </torsional>
              <ode/>
            </friction>
          </surface>
          <laser_retro>0</laser_retro>
          <max_contacts>10</max_contacts>
        </collision>
        <visual name='gripper_finger_link_l_geom_visual'>
          <pose>0 0 0 0 -0 0</pose>
          <geometry>
            <mesh>
              <uri>model://youbot/meshes/gripper/finger.stl</uri>
            </mesh>
          </geometry>
        </visual>
        <gravity>1</gravity>
        <self_collide>0</self_collide>
        <kinematic>0</kinematic>
        <enable_wind>0</enable_wind>
      </link>
      <link name='gripper_finger_link_r'>
        <pose>0.207375 -0.015929 0.409848 -0.085052 0.365926 -0.408445</pose>
        <inertial>
          <pose>0 -0.001 0 0 -0 0</pose>
          <inertia>
            <ixx>0.01</ixx>
            <ixy>0</ixy>
            <ixz>0</ixz>
            <iyy>0.01</iyy>
            <iyz>0</iyz>
            <izz>0.01</izz>
          </inertia>
          <mass>0.01</mass>
        </inertial>
        <collision name='gripper_finger_link_r_geom'>
          <pose>0 0 0 0 -0 0</pose>
          <geometry>
            <mesh>
              <uri>model://youbot/meshes/gripper/finger_convex.stl</uri>
            </mesh>
          </geometry>
          <surface>
            <bounce>
              <restitution_coefficient>0</restitution_coefficient>
              <threshold>0</threshold>
            </bounce>
            <contact>
              <ode>
                <soft_cfm>0</soft_cfm>
                <soft_erp>0.2</soft_erp>
                <kp>1e+13</kp>
                <kd>1e+11</kd>
                <max_vel>-1</max_vel>
                <min_depth>0</min_depth>
              </ode>
            </contact>
            <friction>
              <torsional>
                <ode/>
              </torsional>
              <ode/>
            </friction>
          </surface>
          <laser_retro>0</laser_retro>
          <max_contacts>10</max_contacts>
        </collision>
        <visual name='gripper_finger_link_r_geom_visual'>
          <pose>0 0 0 0 -0 0</pose>
          <geometry>
            <mesh>
              <uri>model://youbot/meshes/gripper/finger.stl</uri>
            </mesh>
          </geometry>
        </visual>
        <gravity>1</gravity>
        <self_collide>0</self_collide>
        <kinematic>0</kinematic>
        <enable_wind>0</enable_wind>
      </link>
      <link name='base_laser_front_link'>
        <pose>0.3 0 -0.03 0 -0 0</pose>
        <inertial>
          <pose>0 0 0 0 -0 0</pose>
          <inertia>
            <ixx>0.1</ixx>
            <ixy>0</ixy>
            <ixz>0</ixz>
            <iyy>0.1</iyy>
            <iyz>0</iyz>
            <izz>0.1</izz>
          </inertia>
          <mass>0.16</mass>
        </inertial>
        <collision name='base_laser_front_link_geom'>
          <pose>0 0 0 0 -0 0</pose>
          <geometry>
            <mesh>
              <uri>model://hokuyo/meshes/hokuyo_convex.stl</uri>
            </mesh>
          </geometry>
          <surface>
            <bounce>
              <restitution_coefficient>0</restitution_coefficient>
              <threshold>0</threshold>
            </bounce>
            <contact>
              <ode>
                <soft_cfm>0</soft_cfm>
                <soft_erp>0.2</soft_erp>
                <kp>1e+13</kp>
                <kd>1e+11</kd>
                <max_vel>-1</max_vel>
                <min_depth>0</min_depth>
              </ode>
            </contact>
            <friction>
              <torsional>
                <ode/>
              </torsional>
              <ode/>
            </friction>
          </surface>
          <laser_retro>0</laser_retro>
          <max_contacts>10</max_contacts>
        </collision>
        <visual name='base_laser_front_link_geom_visual'>
          <pose>0 0 0 0 -0 0</pose>
          <geometry>
            <mesh>
              <uri>model://hokuyo/meshes/hokuyo.dae</uri>
            </mesh>
          </geometry>
        </visual>
        <sensor name='base_laser_front' type='ray'>
          <pose>0 0 0 0 -0 0</pose>
          <ray>
            <scan>
              <horizontal>
                <samples>640</samples>
                <resolution>1</resolution>
                <min_angle>-1.57</min_angle>
                <max_angle>1.57</max_angle>
              </horizontal>
              <vertical>
                <samples>1</samples>
                <min_angle>0</min_angle>
                <max_angle>0</max_angle>
              </vertical>
            </scan>
            <range>
              <min>0.05</min>
              <max>5.6</max>
              <resolution>0.36</resolution>
            </range>
          </ray>
          <always_on>0</always_on>
          <update_rate>10</update_rate>
          <visualize>0</visualize>
        </sensor>
        <gravity>1</gravity>
        <self_collide>0</self_collide>
        <kinematic>0</kinematic>
        <enable_wind>0</enable_wind>
      </link>
      <link name='caster_link_bl'>
        <pose>-0.228 0.158 -0.034 0 -0 0</pose>
        <inertial>
          <pose>0 0 0 0 -0 0</pose>
          <inertia>
            <ixx>0.012412</ixx>
            <ixy>-0.000712</ixy>
            <ixz>0.000503</ixz>
            <iyy>0.015218</iyy>
            <iyz>-4e-06</iyz>
            <izz>0.011764</izz>
          </inertia>
          <mass>0.1</mass>
        </inertial>
        <gravity>1</gravity>
        <self_collide>0</self_collide>
        <kinematic>0</kinematic>
        <enable_wind>0</enable_wind>
      </link>
      <link name='wheel_link_bl'>
        <pose>-0.228 0.158 -0.034 0 -0 0</pose>
        <inertial>
          <pose>0 0 0 0 -0 0</pose>
          <inertia>
            <ixx>0.012412</ixx>
            <ixy>-0.000712</ixy>
            <ixz>0.000503</ixz>
            <iyy>0.015218</iyy>
            <iyz>-4e-06</iyz>
            <izz>0.011764</izz>
          </inertia>
          <mass>0.4</mass>
        </inertial>
        <collision name='wheel_link_bl_geom'>
          <pose>0 0 0 1.5708 -0 0</pose>
          <geometry>
            <cylinder>
              <radius>0.05</radius>
              <length>0.005</length>
            </cylinder>
          </geometry>
          <surface>
            <bounce>
              <restitution_coefficient>0</restitution_coefficient>
              <threshold>0</threshold>
            </bounce>
            <contact>
              <ode>
                <soft_cfm>0</soft_cfm>
                <soft_erp>0.2</soft_erp>
                <kp>1e+13</kp>
                <kd>1e+11</kd>
                <max_vel>-1</max_vel>
                <min_depth>0</min_depth>
              </ode>
            </contact>
            <friction>
              <torsional>
                <ode/>
              </torsional>
              <ode/>
            </friction>
          </surface>
          <laser_retro>0</laser_retro>
          <max_contacts>10</max_contacts>
        </collision>
        <visual name='wheel_link_bl_geom_visual'>
          <pose>0 0 0 0 -0 0</pose>
          <geometry>
            <mesh>
              <uri>model://youbot/meshes/base/back-left_wheel.dae</uri>
            </mesh>
          </geometry>
          <material>
            <script>
              <uri>model://youbot/materials/scripts/youbot.material</uri>
              <name>youbot/Orange</name>
            </script>
          </material>
        </visual>
        <gravity>1</gravity>
        <self_collide>0</self_collide>
        <kinematic>0</kinematic>
        <enable_wind>0</enable_wind>
      </link>
      <link name='caster_link_br'>
        <pose>-0.228 -0.158 -0.034 0 -0 0</pose>
        <inertial>
          <pose>0 0 0 0 -0 0</pose>
          <inertia>
            <ixx>0.012412</ixx>
            <ixy>-0.000712</ixy>
            <ixz>0.000503</ixz>
            <iyy>0.015218</iyy>
            <iyz>-4e-06</iyz>
            <izz>0.011764</izz>
          </inertia>
          <mass>0.1</mass>
        </inertial>
        <gravity>1</gravity>
        <self_collide>0</self_collide>
        <kinematic>0</kinematic>
        <enable_wind>0</enable_wind>
      </link>
      <link name='wheel_link_br'>
        <pose>-0.228 -0.158 -0.034 0 -0 0</pose>
        <inertial>
          <pose>0 0 0 0 -0 0</pose>
          <inertia>
            <ixx>0.012412</ixx>
            <ixy>-0.000712</ixy>
            <ixz>0.000503</ixz>
            <iyy>0.015218</iyy>
            <iyz>-4e-06</iyz>
            <izz>0.011764</izz>
          </inertia>
          <mass>0.4</mass>
        </inertial>
        <collision name='wheel_link_br_geom'>
          <pose>0 0 0 1.5708 -0 0</pose>
          <geometry>
            <cylinder>
              <radius>0.05</radius>
              <length>0.005</length>
            </cylinder>
          </geometry>
          <surface>
            <bounce>
              <restitution_coefficient>0</restitution_coefficient>
              <threshold>0</threshold>
            </bounce>
            <contact>
              <ode>
                <soft_cfm>0</soft_cfm>
                <soft_erp>0.2</soft_erp>
                <kp>1e+13</kp>
                <kd>1e+11</kd>
                <max_vel>-1</max_vel>
                <min_depth>0</min_depth>
              </ode>
            </contact>
            <friction>
              <torsional>
                <ode/>
              </torsional>
              <ode/>
            </friction>
          </surface>
          <laser_retro>0</laser_retro>
          <max_contacts>10</max_contacts>
        </collision>
        <visual name='wheel_link_br_geom_visual'>
          <pose>0 0 0 0 -0 0</pose>
          <geometry>
            <mesh>
              <uri>model://youbot/meshes/base/back-right_wheel.dae</uri>
            </mesh>
          </geometry>
          <material>
            <script>
              <uri>model://youbot/materials/scripts/youbot.material</uri>
              <name>youbot/Orange</name>
            </script>
          </material>
        </visual>
        <gravity>1</gravity>
        <self_collide>0</self_collide>
        <kinematic>0</kinematic>
        <enable_wind>0</enable_wind>
      </link>
      <link name='caster_link_fl'>
        <pose>0.228 0.158 -0.034 0 -0 0</pose>
        <inertial>
          <pose>0 0 0 0 -0 0</pose>
          <inertia>
            <ixx>0.012412</ixx>
            <ixy>-0.000712</ixy>
            <ixz>0.000503</ixz>
            <iyy>0.015218</iyy>
            <iyz>-4e-06</iyz>
            <izz>0.011764</izz>
          </inertia>
          <mass>0.1</mass>
        </inertial>
        <gravity>1</gravity>
        <self_collide>0</self_collide>
        <kinematic>0</kinematic>
        <enable_wind>0</enable_wind>
      </link>
      <link name='wheel_link_fl'>
        <pose>0.228 0.158 -0.034 0 -0 0</pose>
        <inertial>
          <pose>0 0 0 0 -0 0</pose>
          <inertia>
            <ixx>0.012412</ixx>
            <ixy>-0.000712</ixy>
            <ixz>0.000503</ixz>
            <iyy>0.015218</iyy>
            <iyz>-4e-06</iyz>
            <izz>0.011764</izz>
          </inertia>
          <mass>0.4</mass>
        </inertial>
        <collision name='wheel_link_fl_geom'>
          <pose>0 0 0 1.5708 -0 0</pose>
          <geometry>
            <cylinder>
              <radius>0.05</radius>
              <length>0.005</length>
            </cylinder>
          </geometry>
          <surface>
            <bounce>
              <restitution_coefficient>0</restitution_coefficient>
              <threshold>0</threshold>
            </bounce>
            <contact>
              <ode>
                <soft_cfm>0</soft_cfm>
                <soft_erp>0.2</soft_erp>
                <kp>1e+13</kp>
                <kd>1e+11</kd>
                <max_vel>-1</max_vel>
                <min_depth>0</min_depth>
              </ode>
            </contact>
            <friction>
              <torsional>
                <ode/>
              </torsional>
              <ode/>
            </friction>
          </surface>
          <laser_retro>0</laser_retro>
          <max_contacts>10</max_contacts>
        </collision>
        <visual name='wheel_link_fl_geom_visual'>
          <pose>0 0 0 0 -0 0</pose>
          <geometry>
            <mesh>
              <uri>model://youbot/meshes/base/front-left_wheel.dae</uri>
            </mesh>
          </geometry>
          <material>
            <script>
              <uri>model://youbot/materials/scripts/youbot.material</uri>
              <name>youbot/Orange</name>
            </script>
          </material>
        </visual>
        <gravity>1</gravity>
        <self_collide>0</self_collide>
        <kinematic>0</kinematic>
        <enable_wind>0</enable_wind>
      </link>
      <link name='caster_link_fr'>
        <pose>0.228 -0.158 -0.034 0 -0 0</pose>
        <inertial>
          <pose>0 0 0 0 -0 0</pose>
          <inertia>
            <ixx>0.012412</ixx>
            <ixy>-0.000712</ixy>
            <ixz>0.000503</ixz>
            <iyy>0.015218</iyy>
            <iyz>-4e-06</iyz>
            <izz>0.011764</izz>
          </inertia>
          <mass>0.1</mass>
        </inertial>
        <gravity>1</gravity>
        <self_collide>0</self_collide>
        <kinematic>0</kinematic>
        <enable_wind>0</enable_wind>
      </link>
      <link name='wheel_link_fr'>
        <pose>0.228 -0.158 -0.034 0 -0 0</pose>
        <inertial>
          <pose>0 0 0 0 -0 0</pose>
          <inertia>
            <ixx>0.012412</ixx>
            <ixy>-0.000712</ixy>
            <ixz>0.000503</ixz>
            <iyy>0.015218</iyy>
            <iyz>-4e-06</iyz>
            <izz>0.011764</izz>
          </inertia>
          <mass>0.4</mass>
        </inertial>
        <collision name='wheel_link_fr_geom'>
          <pose>0 0 0 1.5708 -0 0</pose>
          <geometry>
            <cylinder>
              <radius>0.05</radius>
              <length>0.005</length>
            </cylinder>
          </geometry>
          <surface>
            <bounce>
              <restitution_coefficient>0</restitution_coefficient>
              <threshold>0</threshold>
            </bounce>
            <contact>
              <ode>
                <soft_cfm>0</soft_cfm>
                <soft_erp>0.2</soft_erp>
                <kp>1e+13</kp>
                <kd>1e+11</kd>
                <max_vel>-1</max_vel>
                <min_depth>0</min_depth>
              </ode>
            </contact>
            <friction>
              <torsional>
                <ode/>
              </torsional>
              <ode/>
            </friction>
          </surface>
          <laser_retro>0</laser_retro>
          <max_contacts>10</max_contacts>
        </collision>
        <visual name='wheel_link_fr_geom_visual'>
          <pose>0 0 0 0 -0 0</pose>
          <geometry>
            <mesh>
              <uri>model://youbot/meshes/base/front-right_wheel.dae</uri>
            </mesh>
          </geometry>
          <material>
            <script>
              <uri>model://youbot/materials/scripts/youbot.material</uri>
              <name>youbot/Orange</name>
            </script>
          </material>
        </visual>
        <gravity>1</gravity>
        <self_collide>0</self_collide>
        <kinematic>0</kinematic>
        <enable_wind>0</enable_wind>
      </link>
      <link name='plate_link'>
        <pose>-0.159 0 0.046 0 -0 0</pose>
        <inertial>
          <pose>0 0 0 0 -0 0</pose>
          <inertia>
            <ixx>0.01</ixx>
            <ixy>0</ixy>
            <ixz>0</ixz>
            <iyy>0.01</iyy>
            <iyz>0</iyz>
            <izz>0.01</izz>
          </inertia>
          <mass>1</mass>
        </inertial>
        <collision name='plate_link_geom'>
          <pose>0 0 0 0 -0 0</pose>
          <geometry>
            <mesh>
              <uri>model://youbot/meshes/plate/plate_convex.stl</uri>
            </mesh>
          </geometry>
          <surface>
            <bounce>
              <restitution_coefficient>0</restitution_coefficient>
              <threshold>0</threshold>
            </bounce>
            <contact>
              <ode>
                <soft_cfm>0</soft_cfm>
                <soft_erp>0.2</soft_erp>
                <kp>1e+13</kp>
                <kd>1e+11</kd>
                <max_vel>-1</max_vel>
                <min_depth>0</min_depth>
              </ode>
            </contact>
            <friction>
              <torsional>
                <ode/>
              </torsional>
              <ode/>
            </friction>
          </surface>
          <laser_retro>0</laser_retro>
          <max_contacts>10</max_contacts>
        </collision>
        <visual name='plate_link_geom_visual'>
          <pose>0 0 0 0 -0 0</pose>
          <geometry>
            <mesh>
              <uri>model://youbot/meshes/plate/plate.dae</uri>
            </mesh>
          </geometry>
        </visual>
        <gravity>1</gravity>
        <self_collide>0</self_collide>
        <kinematic>0</kinematic>
        <enable_wind>0</enable_wind>
      </link>
      <joint name='base_footprint_joint' type='revolute'>
        <pose>0 0 0 0 -0 0</pose>
        <parent>base_footprint</parent>
        <child>base_link</child>
        <axis>
          <dynamics>
            <damping>0</damping>
            <friction>0</friction>
            <spring_reference>0</spring_reference>
            <spring_stiffness>0</spring_stiffness>
          </dynamics>
          <limit>
            <lower>0</lower>
            <upper>0</upper>
            <effort>0</effort>
            <velocity>0</velocity>
          </limit>
          <xyz expressed_in='__model__'>0 0 1</xyz>
        </axis>
      </joint>
      <joint name='arm_joint_0' type='revolute'>
        <pose>0 0 0 0 -0 0</pose>
        <parent>base_link</parent>
        <child>arm_link_0</child>
        <axis>
          <dynamics>
            <damping>0</damping>
            <friction>0</friction>
            <spring_reference>0</spring_reference>
            <spring_stiffness>0</spring_stiffness>
          </dynamics>
          <limit>
            <lower>0</lower>
            <upper>0</upper>
            <effort>0</effort>
            <velocity>0</velocity>
          </limit>
          <xyz expressed_in='__model__'>0 0 1</xyz>
        </axis>
      </joint>
      <joint name='arm_joint_1' type='revolute'>
        <pose>0 0 0 0 -0 0</pose>
        <parent>arm_link_0</parent>
        <child>arm_link_1</child>
        <axis>
          <dynamics>
            <damping>1</damping>
            <friction>0</friction>
            <spring_reference>0</spring_reference>
            <spring_stiffness>0</spring_stiffness>
          </dynamics>
          <limit>
            <lower>0</lower>
            <upper>5.89921</upper>
            <effort>9.5</effort>
          </limit>
          <xyz expressed_in='__model__'>0 0 -1</xyz>
        </axis>
      </joint>
      <joint name='arm_joint_2' type='revolute'>
        <pose>0 0 0 0 -0 0</pose>
        <parent>arm_link_1</parent>
        <child>arm_link_2</child>
        <axis>
          <dynamics>
            <damping>1</damping>
            <friction>0</friction>
            <spring_reference>0</spring_reference>
            <spring_stiffness>0</spring_stiffness>
          </dynamics>
          <limit>
            <lower>0</lower>
            <upper>2.70526</upper>
            <effort>9.5</effort>
            <velocity>-1</velocity>
          </limit>
          <xyz expressed_in='__model__'>-0.173648 -0.984808 0</xyz>
        </axis>
      </joint>
      <joint name='arm_joint_3' type='revolute'>
        <pose>0 0 0 0 -0 0</pose>
        <parent>arm_link_2</parent>
        <child>arm_link_3</child>
        <axis>
          <dynamics>
            <damping>1</damping>
            <friction>0</friction>
            <spring_reference>0</spring_reference>
            <spring_stiffness>0</spring_stiffness>
          </dynamics>
          <limit>
            <lower>-5.18363</lower>
            <upper>0</upper>
            <effort>6</effort>
            <velocity>-1</velocity>
          </limit>
          <xyz expressed_in='__model__'>-0.173648 -0.984808 0</xyz>
        </axis>
      </joint>
      <joint name='arm_joint_4' type='revolute'>
        <pose>0 0 0 0 -0 0</pose>
        <parent>arm_link_3</parent>
        <child>arm_link_4</child>
        <axis>
          <dynamics>
            <damping>1</damping>
            <friction>0</friction>
            <spring_reference>0</spring_reference>
            <spring_stiffness>0</spring_stiffness>
          </dynamics>
          <limit>
            <lower>0</lower>
            <upper>3.57793</upper>
            <effort>2</effort>
            <velocity>-1</velocity>
          </limit>
          <xyz expressed_in='__model__'>-0.173648 -0.984808 0</xyz>
        </axis>
      </joint>
      <joint name='arm_joint_5' type='revolute'>
        <pose>0 0 0 0 -0 0</pose>
        <parent>arm_link_4</parent>
        <child>arm_link_5</child>
        <axis>
          <dynamics>
            <damping>1</damping>
            <friction>0</friction>
            <spring_reference>0</spring_reference>
            <spring_stiffness>0</spring_stiffness>
          </dynamics>
          <limit>
            <lower>0</lower>
            <upper>5.84685</upper>
            <effort>1</effort>
            <velocity>-1</velocity>
          </limit>
          <xyz expressed_in='__model__'>-0.360933 0.063642 -0.930418</xyz>
        </axis>
      </joint>
      <joint name='gripper_palm_joint' type='revolute'>
        <pose>0 0 0 0 -0 0</pose>
        <parent>arm_link_5</parent>
        <child>gripper_palm_link</child>
        <axis>
          <dynamics>
            <damping>0</damping>
            <friction>0</friction>
            <spring_reference>0</spring_reference>
            <spring_stiffness>0</spring_stiffness>
          </dynamics>
          <limit>
            <lower>0</lower>
            <upper>0</upper>
            <effort>0</effort>
            <velocity>0</velocity>
          </limit>
          <xyz expressed_in='__model__'>0 0 1</xyz>
        </axis>
      </joint>
      <joint name='gripper_finger_joint_l' type='prismatic'>
        <pose>0 0 0 0 -0 0</pose>
        <parent>gripper_palm_link</parent>
        <child>gripper_finger_link_l</child>
        <axis>
          <dynamics>
            <damping>1</damping>
            <friction>0</friction>
            <spring_reference>0</spring_reference>
            <spring_stiffness>0</spring_stiffness>
          </dynamics>
          <limit>
            <lower>0</lower>
            <upper>0.0115</upper>
            <effort>1</effort>
            <velocity>-1</velocity>
          </limit>
          <xyz expressed_in='__model__'>0.367852 0.926495 -0.079325</xyz>
        </axis>
      </joint>
      <joint name='gripper_finger_joint_r' type='prismatic'>
        <pose>0 0 0 0 -0 0</pose>
        <parent>gripper_palm_link</parent>
        <child>gripper_finger_link_r</child>
        <axis>
          <dynamics>
            <damping>1</damping>
            <friction>0</friction>
            <spring_reference>0</spring_reference>
            <spring_stiffness>0</spring_stiffness>
          </dynamics>
          <limit>
            <lower>0</lower>
            <upper>0.0115</upper>
            <effort>1</effort>
            <velocity>-1</velocity>
          </limit>
          <xyz expressed_in='__model__'>-0.367852 -0.926495 0.079325</xyz>
        </axis>
      </joint>
      <joint name='base_laser_front_hokuyo_urg04_laser_joint' type='revolute'>
        <pose>0 0 0 0 -0 0</pose>
        <parent>base_link</parent>
        <child>base_laser_front_link</child>
        <axis>
          <dynamics>
            <damping>0</damping>
            <friction>0</friction>
            <spring_reference>0</spring_reference>
            <spring_stiffness>0</spring_stiffness>
          </dynamics>
          <limit>
            <lower>0</lower>
            <upper>0</upper>
            <effort>0</effort>
            <velocity>0</velocity>
          </limit>
          <xyz expressed_in='__model__'>0 0 1</xyz>
        </axis>
      </joint>
      <joint name='caster_joint_bl' type='revolute'>
        <pose>0 0 0 0 -0 0</pose>
        <parent>base_link</parent>
        <child>caster_link_bl</child>
        <axis>
          <dynamics>
            <damping>1</damping>
            <friction>0</friction>
            <spring_reference>0</spring_reference>
            <spring_stiffness>0</spring_stiffness>
          </dynamics>
          <limit>
            <effort>1</effort>
            <lower>-1e+16</lower>
            <upper>1e+16</upper>
          </limit>
          <xyz expressed_in='__model__'>0 0 1</xyz>
        </axis>
      </joint>
      <joint name='wheel_joint_bl' type='revolute'>
        <pose>0 0 0 0 -0 0</pose>
        <parent>caster_link_bl</parent>
        <child>wheel_link_bl</child>
        <axis>
          <dynamics>
            <damping>1</damping>
            <friction>0</friction>
            <spring_reference>0</spring_reference>
            <spring_stiffness>0</spring_stiffness>
          </dynamics>
          <limit>
            <effort>1</effort>
            <lower>-1e+16</lower>
            <upper>1e+16</upper>
          </limit>
          <xyz expressed_in='__model__'>0 1 0</xyz>
        </axis>
      </joint>
      <joint name='caster_joint_br' type='revolute'>
        <pose>0 0 0 0 -0 0</pose>
        <parent>base_link</parent>
        <child>caster_link_br</child>
        <axis>
          <dynamics>
            <damping>1</damping>
            <friction>0</friction>
            <spring_reference>0</spring_reference>
            <spring_stiffness>0</spring_stiffness>
          </dynamics>
          <limit>
            <effort>1</effort>
            <lower>-1e+16</lower>
            <upper>1e+16</upper>
          </limit>
          <xyz expressed_in='__model__'>0 0 1</xyz>
        </axis>
      </joint>
      <joint name='wheel_joint_br' type='revolute'>
        <pose>0 0 0 0 -0 0</pose>
        <parent>caster_link_br</parent>
        <child>wheel_link_br</child>
        <axis>
          <dynamics>
            <damping>1</damping>
            <friction>0</friction>
            <spring_reference>0</spring_reference>
            <spring_stiffness>0</spring_stiffness>
          </dynamics>
          <limit>
            <effort>1</effort>
            <lower>-1e+16</lower>
            <upper>1e+16</upper>
          </limit>
          <xyz expressed_in='__model__'>0 1 0</xyz>
        </axis>
      </joint>
      <joint name='caster_joint_fl' type='revolute'>
        <pose>0 0 0 0 -0 0</pose>
        <parent>base_link</parent>
        <child>caster_link_fl</child>
        <axis>
          <dynamics>
            <damping>1</damping>
            <friction>0</friction>
            <spring_reference>0</spring_reference>
            <spring_stiffness>0</spring_stiffness>
          </dynamics>
          <limit>
            <effort>1</effort>
            <lower>-1e+16</lower>
            <upper>1e+16</upper>
          </limit>
          <xyz expressed_in='__model__'>0 0 1</xyz>
        </axis>
      </joint>
      <joint name='wheel_joint_fl' type='revolute'>
        <pose>0 0 0 0 -0 0</pose>
        <parent>caster_link_fl</parent>
        <child>wheel_link_fl</child>
        <axis>
          <dynamics>
            <damping>1</damping>
            <friction>0</friction>
            <spring_reference>0</spring_reference>
            <spring_stiffness>0</spring_stiffness>
          </dynamics>
          <limit>
            <effort>1</effort>
            <lower>-1e+16</lower>
            <upper>1e+16</upper>
          </limit>
          <xyz expressed_in='__model__'>0 1 0</xyz>
        </axis>
      </joint>
      <joint name='caster_joint_fr' type='revolute'>
        <pose>0 0 0 0 -0 0</pose>
        <parent>base_link</parent>
        <child>caster_link_fr</child>
        <axis>
          <dynamics>
            <damping>1</damping>
            <friction>0</friction>
            <spring_reference>0</spring_reference>
            <spring_stiffness>0</spring_stiffness>
          </dynamics>
          <limit>
            <effort>1</effort>
            <lower>-1e+16</lower>
            <upper>1e+16</upper>
          </limit>
          <xyz expressed_in='__model__'>0 0 1</xyz>
        </axis>
      </joint>
      <joint name='wheel_joint_fr' type='revolute'>
        <pose>0 0 0 0 -0 0</pose>
        <parent>caster_link_fr</parent>
        <child>wheel_link_fr</child>
        <axis>
          <dynamics>
            <damping>1</damping>
            <friction>0</friction>
            <spring_reference>0</spring_reference>
            <spring_stiffness>0</spring_stiffness>
          </dynamics>
          <limit>
            <effort>1</effort>
            <lower>-1e+16</lower>
            <upper>1e+16</upper>
          </limit>
          <xyz expressed_in='__model__'>0 1 0</xyz>
        </axis>
      </joint>
      <joint name='plate_joint' type='revolute'>
        <parent>base_link</parent>
        <child>plate_link</child>
        <axis>
          <dynamics>
            <damping>0</damping>
            <friction>0</friction>
            <spring_reference>0</spring_reference>
            <spring_stiffness>0</spring_stiffness>
          </dynamics>
          <limit>
            <lower>0</lower>
            <upper>0</upper>
            <effort>0</effort>
            <velocity>0</velocity>
          </limit>
          <xyz expressed_in='__model__'>0 0 1</xyz>
        </axis>
      </joint>
      <static>0</static>
    </model>
    <model name='Construction Cone'>
      <link name='link'>
        <collision name='collision'>
          <geometry>
            <mesh>
              <scale>10 10 10</scale>
              <uri>model://construction_cone/meshes/construction_cone.dae</uri>
            </mesh>
          </geometry>
          <max_contacts>10</max_contacts>
          <surface>
            <contact>
              <ode/>
            </contact>
            <bounce/>
            <friction>
              <torsional>
                <ode/>
              </torsional>
              <ode/>
            </friction>
          </surface>
        </collision>
        <visual name='visual'>
          <geometry>
            <mesh>
              <scale>10 10 10</scale>
              <uri>model://construction_cone/meshes/construction_cone.dae</uri>
            </mesh>
          </geometry>
        </visual>
        <self_collide>0</self_collide>
        <inertial>
          <pose>0 0 0 0 -0 0</pose>
          <inertia>
            <ixx>1</ixx>
            <ixy>0</ixy>
            <ixz>0</ixz>
            <iyy>1</iyy>
            <iyz>0</iyz>
            <izz>1</izz>
          </inertia>
          <mass>1</mass>
        </inertial>
        <enable_wind>0</enable_wind>
        <kinematic>0</kinematic>
      </link>
      <pose>1.47437 2.06266 -0 0 -1e-06 0</pose>
    </model>
    <model name='drc_practice_blue_cylinder'>
      <static>1</static>
      <link name='link'>
        <visual name='visual'>
          <geometry>
            <mesh>
              <uri>model://drc_practice_blue_cylinder/meshes/cylinder.dae</uri>
            </mesh>
          </geometry>
        </visual>
        <collision name='collision'>
          <geometry>
            <mesh>
              <uri>model://drc_practice_blue_cylinder/meshes/cylinder.dae</uri>
            </mesh>
          </geometry>
          <max_contacts>10</max_contacts>
          <surface>
            <contact>
              <ode/>
            </contact>
            <bounce/>
            <friction>
              <torsional>
                <ode/>
              </torsional>
              <ode/>
            </friction>
          </surface>
        </collision>
        <self_collide>0</self_collide>
        <enable_wind>0</enable_wind>
        <kinematic>0</kinematic>
      </link>
      <pose>3.76315 -3.28234 0 0 -0 0</pose>
    </model>
    <model name='number6'>
      <pose>-3.42605 2.83365 0.4 0 -0 0</pose>
      <static>1</static>
      <link name='link'>
        <visual name='visual'>
          <geometry>
            <mesh>
              <uri>model://number1/meshes/number.dae</uri>
            </mesh>
          </geometry>
          <material>
            <script>
              <uri>model://number6/materials/scripts</uri>
              <uri>model://number6/materials/textures</uri>
              <name>Number/Six</name>
            </script>
          </material>
        </visual>
        <self_collide>0</self_collide>
        <enable_wind>0</enable_wind>
        <kinematic>0</kinematic>
      </link>
    </model>
    <model name='Construction Cone_clone'>
      <link name='link'>
        <collision name='collision'>
          <geometry>
            <mesh>
              <scale>10 10 10</scale>
              <uri>model://construction_cone/meshes/construction_cone.dae</uri>
            </mesh>
          </geometry>
          <max_contacts>10</max_contacts>
          <surface>
            <contact>
              <ode/>
            </contact>
            <bounce/>
            <friction>
              <torsional>
                <ode/>
              </torsional>
              <ode/>
            </friction>
          </surface>
        </collision>
        <visual name='visual'>
          <geometry>
            <mesh>
              <scale>10 10 10</scale>
              <uri>model://construction_cone/meshes/construction_cone.dae</uri>
            </mesh>
          </geometry>
        </visual>
        <self_collide>0</self_collide>
        <inertial>
          <pose>0 0 0 0 -0 0</pose>
          <inertia>
            <ixx>1</ixx>
            <ixy>0</ixy>
            <ixz>0</ixz>
            <iyy>1</iyy>
            <iyz>0</iyz>
            <izz>1</izz>
          </inertia>
          <mass>1</mass>
        </inertial>
        <enable_wind>0</enable_wind>
        <kinematic>0</kinematic>
      </link>
      <pose>4.86388 -1.28362 -5e-06 -4e-06 1e-06 0</pose>
    </model>
    <model name='Construction Cone_clone_0'>
      <link name='link'>
        <collision name='collision'>
          <geometry>
            <mesh>
              <scale>10 10 10</scale>
              <uri>model://construction_cone/meshes/construction_cone.dae</uri>
            </mesh>
          </geometry>
          <max_contacts>10</max_contacts>
          <surface>
            <contact>
              <ode/>
            </contact>
            <bounce/>
            <friction>
              <torsional>
                <ode/>
              </torsional>
              <ode/>
            </friction>
          </surface>
        </collision>
        <visual name='visual'>
          <geometry>
            <mesh>
              <scale>10 10 10</scale>
              <uri>model://construction_cone/meshes/construction_cone.dae</uri>
            </mesh>
          </geometry>
        </visual>
        <self_collide>0</self_collide>
        <inertial>
          <pose>0 0 0 0 -0 0</pose>
          <inertia>
            <ixx>1</ixx>
            <ixy>0</ixy>
            <ixz>0</ixz>
            <iyy>1</iyy>
            <iyz>0</iyz>
            <izz>1</izz>
          </inertia>
          <mass>1</mass>
        </inertial>
        <enable_wind>0</enable_wind>
        <kinematic>0</kinematic>
      </link>
      <pose>3.78125 2.05908 -0 0 -1e-06 0</pose>
    </model>
    <model name='Construction Cone_clone_1'>
      <link name='link'>
        <collision name='collision'>
          <geometry>
            <mesh>
              <scale>10 10 10</scale>
              <uri>model://construction_cone/meshes/construction_cone.dae</uri>
            </mesh>
          </geometry>
          <max_contacts>10</max_contacts>
          <surface>
            <contact>
              <ode/>
            </contact>
            <bounce/>
            <friction>
              <torsional>
                <ode/>
              </torsional>
              <ode/>
            </friction>
          </surface>
        </collision>
        <visual name='visual'>
          <geometry>
            <mesh>
              <scale>10 10 10</scale>
              <uri>model://construction_cone/meshes/construction_cone.dae</uri>
            </mesh>
          </geometry>
        </visual>
        <self_collide>0</self_collide>
        <inertial>
          <pose>0 0 0 0 -0 0</pose>
          <inertia>
            <ixx>1</ixx>
            <ixy>0</ixy>
            <ixz>0</ixz>
            <iyy>1</iyy>
            <iyz>0</iyz>
            <izz>1</izz>
          </inertia>
          <mass>1</mass>
        </inertial>
        <enable_wind>0</enable_wind>
        <kinematic>0</kinematic>
      </link>
      <pose>3.03821 3.74159 -0 0 -0 0</pose>
    </model>
    <model name='Construction Cone_clone_2'>
      <link name='link'>
        <collision name='collision'>
          <geometry>
            <mesh>
              <scale>10 10 10</scale>
              <uri>model://construction_cone/meshes/construction_cone.dae</uri>
            </mesh>
          </geometry>
          <max_contacts>10</max_contacts>
          <surface>
            <contact>
              <ode/>
            </contact>
            <bounce/>
            <friction>
              <torsional>
                <ode/>
              </torsional>
              <ode/>
            </friction>
          </surface>
        </collision>
        <visual name='visual'>
          <geometry>
            <mesh>
              <scale>10 10 10</scale>
              <uri>model://construction_cone/meshes/construction_cone.dae</uri>
            </mesh>
          </geometry>
        </visual>
        <self_collide>0</self_collide>
        <inertial>
          <pose>0 0 0 0 -0 0</pose>
          <inertia>
            <ixx>1</ixx>
            <ixy>0</ixy>
            <ixz>0</ixz>
            <iyy>1</iyy>
            <iyz>0</iyz>
            <izz>1</izz>
          </inertia>
          <mass>1</mass>
        </inertial>
        <enable_wind>0</enable_wind>
        <kinematic>0</kinematic>
      </link>
      <pose>-2.70216 4.04821 -0 0 -0 0</pose>
    </model>
    <model name='Construction Cone_clone_3'>
      <link name='link'>
        <collision name='collision'>
          <geometry>
            <mesh>
              <scale>10 10 10</scale>
              <uri>model://construction_cone/meshes/construction_cone.dae</uri>
            </mesh>
          </geometry>
          <max_contacts>10</max_contacts>
          <surface>
            <contact>
              <ode/>
            </contact>
            <bounce/>
            <friction>
              <torsional>
                <ode/>
              </torsional>
              <ode/>
            </friction>
          </surface>
        </collision>
        <visual name='visual'>
          <geometry>
            <mesh>
              <scale>10 10 10</scale>
              <uri>model://construction_cone/meshes/construction_cone.dae</uri>
            </mesh>
          </geometry>
        </visual>
        <self_collide>0</self_collide>
        <inertial>
          <pose>0 0 0 0 -0 0</pose>
          <inertia>
            <ixx>1</ixx>
            <ixy>0</ixy>
            <ixz>0</ixz>
            <iyy>1</iyy>
            <iyz>0</iyz>
            <izz>1</izz>
          </inertia>
          <mass>1</mass>
        </inertial>
        <enable_wind>0</enable_wind>
        <kinematic>0</kinematic>
      </link>
      <pose>-3.84854 -3.14281 -4e-06 3e-06 -0 0</pose>
    </model>
    <model name='Construction Cone_clone_4'>
      <link name='link'>
        <collision name='collision'>
          <geometry>
            <mesh>
              <scale>10 10 10</scale>
              <uri>model://construction_cone/meshes/construction_cone.dae</uri>
            </mesh>
          </geometry>
          <max_contacts>10</max_contacts>
          <surface>
            <contact>
              <ode/>
            </contact>
            <bounce/>
            <friction>
              <torsional>
                <ode/>
              </torsional>
              <ode/>
            </friction>
          </surface>
        </collision>
        <visual name='visual'>
          <geometry>
            <mesh>
              <scale>10 10 10</scale>
              <uri>model://construction_cone/meshes/construction_cone.dae</uri>
            </mesh>
          </geometry>
        </visual>
        <self_collide>0</self_collide>
        <inertial>
          <pose>0 0 0 0 -0 0</pose>
          <inertia>
            <ixx>1</ixx>
            <ixy>0</ixy>
            <ixz>0</ixz>
            <iyy>1</iyy>
            <iyz>0</iyz>
            <izz>1</izz>
          </inertia>
          <mass>1</mass>
        </inertial>
        <enable_wind>0</enable_wind>
        <kinematic>0</kinematic>
      </link>
      <pose>-2.07238 -4.77459 -1e-05 0 -0 0</pose>
    </model>
    <model name='Construction Cone_clone_5'>
      <link name='link'>
        <collision name='collision'>
          <geometry>
            <mesh>
              <scale>10 10 10</scale>
              <uri>model://construction_cone/meshes/construction_cone.dae</uri>
            </mesh>
          </geometry>
          <max_contacts>10</max_contacts>
          <surface>
            <contact>
              <ode/>
            </contact>
            <bounce/>
            <friction>
              <torsional>
                <ode/>
              </torsional>
              <ode/>
            </friction>
          </surface>
        </collision>
        <visual name='visual'>
          <geometry>
            <mesh>
              <scale>10 10 10</scale>
              <uri>model://construction_cone/meshes/construction_cone.dae</uri>
            </mesh>
          </geometry>
        </visual>
        <self_collide>0</self_collide>
        <inertial>
          <pose>0 0 0 0 -0 0</pose>
          <inertia>
            <ixx>1</ixx>
            <ixy>0</ixy>
            <ixz>0</ixz>
            <iyy>1</iyy>
            <iyz>0</iyz>
            <izz>1</izz>
          </inertia>
          <mass>1</mass>
        </inertial>
        <enable_wind>0</enable_wind>
        <kinematic>0</kinematic>
      </link>
      <pose>1.64855 -0.595661 -6e-06 2e-06 -0 0</pose>
    </model>
    <model name='Construction Cone_clone_6'>
      <link name='link'>
        <collision name='collision'>
          <geometry>
            <mesh>
              <scale>10 10 10</scale>
              <uri>model://construction_cone/meshes/construction_cone.dae</uri>
            </mesh>
          </geometry>
          <max_contacts>10</max_contacts>
          <surface>
            <contact>
              <ode/>
            </contact>
            <bounce/>
            <friction>
              <torsional>
                <ode/>
              </torsional>
              <ode/>
            </friction>
          </surface>
        </collision>
        <visual name='visual'>
          <geometry>
            <mesh>
              <scale>10 10 10</scale>
              <uri>model://construction_cone/meshes/construction_cone.dae</uri>
            </mesh>
          </geometry>
        </visual>
        <self_collide>0</self_collide>
        <inertial>
          <pose>0 0 0 0 -0 0</pose>
          <inertia>
            <ixx>1</ixx>
            <ixy>0</ixy>
            <ixz>0</ixz>
            <iyy>1</iyy>
            <iyz>0</iyz>
            <izz>1</izz>
          </inertia>
          <mass>1</mass>
        </inertial>
        <enable_wind>0</enable_wind>
        <kinematic>0</kinematic>
      </link>
      <pose>-1.73672 0.238001 -0 0 -0 0</pose>
    </model>
  </world>
</sdf>
